Workbook

Sheet قوى عاملة تحفيظ أولي (2)
A4: م | B4: اسم المدرسة | C4: مدير | E4: وكيل | G4: مدرس | I4: اخرى | K4: الإجمالي
C5: ذ | D5: ث | E5: ذ | F5: ث | G5: ذ | H5: ث | I5: ذ | J5: ث | K5: ذ | L5: ث | M5: ج
A6: 1
A7: 2
A8: 3
A9: 4
A10: 5
A11: 6
A12: 7
A13: 8
A14: 9
A15: 10
A16: 11
A17: 12
... A25: 20
A26: الاجمالي | C26: =SUM(C6:C25) -> 0 | D26: =SUM(D6:D25) -> 0 | E26: =SUM(E6:E25) -> 0 | F26: =SUM(F6:F25) -> 0 | G26: =SUM(G6:G25) -> 0 | H26: =SUM(H6:H25) -> 0 | I26: =SUM(I6:I25) -> 0 | J26: =SUM(J6:J25) -> 0 | ... M26: =SUM(M6:M25) -> 0
A28: رئيس قسم التخطيط والإحصاء | K28: مدير إدارة التربية في المديرية

Sheet مدرسة حكومي- أهلي طلاب ثانوي 
D7: م | E7: اسم المدسة | F7: البيان | G7: الأول الثانوي | K7: الثاني الثانوي - علمي | O7: الثاني الثانوي - أدبي | S7: الثالث الثانوي - علمي | W7: الثالث الثانوي - أدبي | AA7: اجمالي عام
G9: شعب | H9: ذكور | I9: اناث | J9: اجمالي | K9: شعب | L9: ذكور | M9: اناث | N9: اجمالي | O9: شعب | P9: ذكور | Q9: اناث | R9: اجمالي | S9: شعب | T9: ذكور | U9: اناث | V9: اجمالي | W9: شعب | X9: ذكور | Y9: اناث | Z9: اجمالي | AA9: شعب | AB9: ذكور | AC9: اناث | AD9: اجمالي
D10: 1 | F10: ناجح
F11: راسب
E14: مدير المدرسة | H14: رئيس قسم التخطيط والاحصاء | V14: مدير ادارة التربية والتعليم بالمديرية

Sheet اجمالي طلاب ثانوي حكومي +اهلي
D7: م | E7: اسم المدسة | F7: البيان | G7: الأول الثانوي | K7: الثاني الثانوي - علمي | O7: الثاني الثانوي - أدبي | S7: الثالث الثانوي - علمي | W7: الثالث الثانوي - أدبي | AA7: اجمالي عام
G9: شعب | H9: ذكور | I9: اناث | J9: اجمالي | K9: شعب | L9: ذكور | M9: اناث | N9: اجمالي | O9: شعب | P9: ذكور | Q9: اناث | R9: اجمالي | S9: شعب | T9: ذكور | U9: اناث | V9: اجمالي | W9: شعب | X9: ذكور | Y9: اناث | Z9: اجمالي | AA9: شعب | AB9: ذكور | AC9: اناث | AD9: اجمالي
D10: 1 | F10: ناجح
F11: راسب
D12: 2 | F12: ناجح
F13: راسب
D14: 3 | F14: ناجح
F15: راسب
D16: 4 | F16: ناجح
F17: راسب
D18: 5 | F18: ناجح
F19: راسب
D20: 6 | F20: ناجح
F21: راسب
D22: 7 | F22: ناجح
F23: راسب
D24: 8 | F24: ناجح
F25: راسب
D26: 9 | F26: ناجح
F27: راسب
D28: 10 | F28: ناجح
F29: راسب
D30: 11 | F30: ناجح
F31: راسب
D32: 12 | F32: ناجح
F33: راسب
D34: 13 | F34: ناجح
F35: راسب
D36: 14 | F36: ناجح
F37: راسب
D38: 15 | F38: ناجح
F39: راسب
D40: 16 | F40: ناجح
F41: راسب
D42: 17 | F42: ناجح
F43: راسب
D44: 18 | F44: ناجح
F45: راسب
D46: 19 | F46: ناجح
F47: راسب
...

Sheet طلاب ثانوي حكومي تجميع مديرية
D7: م | E7: اسم المدسة | F7: البيان | G7: الأول الثانوي | K7: الثاني الثانوي - علمي | O7: الثاني الثانوي - أدبي | S7: الثالث الثانوي - علمي | W7: الثالث الثانوي - أدبي | AA7: اجمالي عام
G9: شعب | H9: ذكور | I9: اناث | J9: اجمالي | K9: شعب | L9: ذكور | M9: اناث | N9: اجمالي | O9: شعب | P9: ذكور | Q9: اناث | R9: اجمالي | S9: شعب | T9: ذكور | U9: اناث | V9: اجمالي | W9: شعب | X9: ذكور | Y9: اناث | Z9: اجمالي | AA9: شعب | AB9: ذكور | AC9: اناث | AD9: اجمالي
D10: 1 | F10: ناجح
F11: راسب
D12: 2 | F12: ناجح
F13: راسب
D14: 3 | F14: ناجح
F15: راسب
D16: 4 | F16: ناجح
F17: راسب
D18: 5 | F18: ناجح
F19: راسب
D20: 6 | F20: ناجح
F21: راسب
D22: 7 | F22: ناجح
F23: راسب
D24: 8 | F24: ناجح
F25: راسب
D26: 9 | F26: ناجح
F27: راسب
D28: 10 | F28: ناجح
F29: راسب
D30: 11 | F30: ناجح
F31: راسب
D32: 12 | F32: ناجح
F33: راسب
D34: 13 | F34: ناجح
F35: راسب
D36: 14 | F36: ناجح
F37: راسب
D38: 15 | F38: ناجح
F39: راسب
D40: 16 | F40: ناجح
F41: راسب
D42: 17 | F42: ناجح
F43: راسب
D44: 18 | F44: ناجح
F45: راسب
D46: 19 | F46: ناجح
F47: راسب
...

Sheet مدرسة طلاب اساسي حكومي أهلي  
Q5: الإحصائية العامة بإجمالي طلاب و طالبات المرحلة الأساسية حكومي /أهلي بمدرسة/................... مديرية/.............. للعام الدراسي 2025 - 2026م
D7: م | E7: اسم المدرسة | F7: البيان | G7: الأول | K7: الثاني | O7: الثالث | S7: الرابع | W7: الخامس | AA7: السادس | AE7: السابع | AI7: الثامن | AM7: التاسع | AQ7: الإجمالي العام
G9: شعب | H9: ذكور | I9: اناث | J9: اجمالي | K9: شعب | L9: ذكور | M9: اناث | N9: اجمالي | O9: شعب | P9: ذكور | Q9: اناث | R9: اجمالي | S9: شعب | T9: ذكور | U9: اناث | V9: اجمالي | W9: شعب | X9: ذكور | Y9: اناث | Z9: اجمالي | AA9: شعب | AB9: ذكور | AC9: اناث | AD9: اجمالي | AE9: شعب | AF9: ذكور | AG9: اناث | AH9: اجمالي | AI9: شعب | AJ9: ذكور | AK9: اناث | AL9: اجمالي | AM9: شعب | AN9: ذكور | AO9: اناث | AP9: اجمالي | AQ9: شعب | AR9: ذكور | AS9: اناث | AT9: اجمالي
D10: 1 | F10: ناجح
F11: راسب
AI16: مدير ادارة التربية والتعليم بالمديرية
E17: مدير المدرسة | L17: رئيس قسم التخطيط والاحصاء

Sheet   تجميع م طلاب اساسي حكومي 
Q5: الإحصائية العامة بإجمالي طلاب و طالبات المرحلة الأساسية حكومي بمديرية/.............. للعام الدراسي 2025 - 2026م
D7: م | E7: اسم المدرسة | F7: البيان | G7: الأول | K7: الثاني | O7: الثالث | S7: الرابع | W7: الخامس | AA7: السادس | AE7: السابع | AI7: الثامن | AM7: التاسع | AQ7: الإجمالي العام
G9: شعب | H9: ذكور | I9: اناث | J9: اجمالي | K9: شعب | L9: ذكور | M9: اناث | N9: اجمالي | O9: شعب | P9: ذكور | Q9: اناث | R9: اجمالي | S9: شعب | T9: ذكور | U9: اناث | V9: اجمالي | W9: شعب | X9: ذكور | Y9: اناث | Z9: اجمالي | AA9: شعب | AB9: ذكور | AC9: اناث | AD9: اجمالي | AE9: شعب | AF9: ذكور | AG9: اناث | AH9: اجمالي | AI9: شعب | AJ9: ذكور | AK9: اناث | AL9: اجمالي | AM9: شعب | AN9: ذكور | AO9: اناث | AP9: اجمالي | AQ9: شعب | AR9: ذكور | AS9: اناث | AT9: اجمالي
D10: 1 | F10: ناجح
F11: راسب
D12: 2 | F12: ناجح
F13: راسب
D14: 3 | F14: ناجح
F15: راسب
D16: 4 | F16: ناجح
F17: راسب
D18: 5 | F18: ناجح
F19: راسب
D20: 6 | F20: ناجح
F21: راسب
D22: 7 | F22: ناجح
F23: راسب
D24: 8 | F24: ناجح
F25: راسب
D26: 9 | F26: ناجح
F27: راسب
D28: 10 | F28: ناجح
F29: راسب
D30: 11 | F30: ناجح
F31: راسب
D32: 12 | F32: ناجح
F33: راسب
D34: 13 | F34: ناجح
F35: راسب
D36: 14 | F36: ناجح
F37: راسب
D38: 15 | F38: ناجح
F39: راسب
D40: 16 | F40: ناجح
F41: راسب
D42: 17 | F42: ناجح
F43: راسب
D44: 18 | F44: ناجح
F45: راسب
D46: 19 | F46: ناجح
...

Sheet طلاب اساسي اهلي تجميع م
Q5: الإحصائية العامة لطلاب و طالبات المرحلة الأساسية اهلي بمديرية/.............. للعام الدراسي 2025 - 2026م
D7: م | E7: اسم المدرسة | F7: البيان | G7: الأول | K7: الثاني | O7: الثالث | S7: الرابع | W7: الخامس | AA7: السادس | AE7: السابع | AI7: الثامن | AM7: التاسع | AQ7: الإجمالي العام
G9: شعب | H9: ذكور | I9: اناث | J9: اجمالي | K9: شعب | L9: ذكور | M9: اناث | N9: اجمالي | O9: شعب | P9: ذكور | Q9: اناث | R9: اجمالي | S9: شعب | T9: ذكور | U9: اناث | V9: اجمالي | W9: شعب | X9: ذكور | Y9: اناث | Z9: اجمالي | AA9: شعب | AB9: ذكور | AC9: اناث | AD9: اجمالي | AE9: شعب | AF9: ذكور | AG9: اناث | AH9: اجمالي | AI9: شعب | AJ9: ذكور | AK9: اناث | AL9: اجمالي | AM9: شعب | AN9: ذكور | AO9: اناث | AP9: اجمالي | AQ9: شعب | AR9: ذكور | AS9: اناث | AT9: اجمالي
D10: 1 | F10: ناجح
F11: راسب
D12: 2 | F12: ناجح
F13: راسب
D14: 3 | F14: ناجح
F15: راسب
D16: 4 | F16: ناجح
F17: راسب
D18: 5 | F18: ناجح
F19: راسب
D20: 6 | F20: ناجح
F21: راسب
D22: 7 | F22: ناجح
F23: راسب
D24: 8 | F24: ناجح
F25: راسب
D26: 9 | F26: ناجح
F27: راسب
D28: 10 | F28: ناجح
F29: راسب
D30: 11 | F30: ناجح
F31: راسب
D32: 12 | F32: ناجح
F33: راسب
D34: 13 | F34: ناجح
F35: راسب
D36: 14 | F36: ناجح
F37: راسب
D38: 15 | F38: ناجح
F39: راسب
D40: 16 | F40: ناجح
F41: راسب
D42: 17 | F42: ناجح
F43: راسب
D44: 18 | F44: ناجح
F45: راسب
D46: 19 | F46: ناجح
...

Sheet طلاب ثانوي اهلي تجميع م
D7: م | E7: اسم المدرسة | F7: البيان | G7: الأول الثانوي | K7: الثاني الثانوي - علمي | O7: الثاني الثانوي - أدبي | S7: الثالث الثانوي - علمي | W7: الثالث الثانوي - أدبي | AA7: اجمالي عام
G9: شعب | H9: ذكور | I9: اناث | J9: اجمالي | K9: شعب | L9: ذكور | M9: اناث | N9: اجمالي | O9: شعب | P9: ذكور | Q9: اناث | R9: اجمالي | S9: شعب | T9: ذكور | U9: اناث | V9: اجمالي | W9: شعب | X9: ذكور | Y9: اناث | Z9: اجمالي | AA9: شعب | AB9: ذكور | AC9: اناث | AD9: اجمالي
D10: 1 | F10: ناجح
F11: راسب
D12: 2 | F12: ناجح
F13: راسب
D14: 3 | F14: ناجح
F15: راسب
D16: 4 | F16: ناجح
F17: راسب
D18: 5 | F18: ناجح
F19: راسب
D20: 6 | F20: ناجح
F21: راسب
D22: 7 | F22: ناجح
F23: راسب
D24: 8 | F24: ناجح
F25: راسب
D26: 9 | F26: ناجح
F27: راسب
D28: 10 | F28: ناجح
F29: راسب
D30: 11 | F30: ناجح
F31: راسب
D32: 12 | F32: ناجح
F33: راسب
D34: 13 | F34: ناجح
F35: راسب
D36: 14 | F36: ناجح
F37: راسب
D38: 15 | F38: ناجح
F39: راسب
D40: 16 | F40: ناجح
F41: راسب
D42: 17 | F42: ناجح
F43: راسب
D44: 18 | F44: ناجح
F45: راسب
D46: 19 | F46: ناجح
F47: راسب
...

Sheet اجمالي طلاب اساسي حكومي+اهلي
Q5: الإحصائية العامة بإجمالي طلاب و طالبات المرحلة الأساسية حكومي + اهلي بمديرية/.............. للعام الدراسي 2023 - 2024م
D7: م | E7: اسم المدرسة | F7: البيان | G7: الأول | K7: الثاني | O7: الثالث | S7: الرابع | W7: الخامس | AA7: السادس | AE7: السابع | AI7: الثامن | AM7: التاسع | AQ7: الإجمالي العام
G9: شعب | H9: ذكور | I9: اناث | J9: اجمالي | K9: شعب | L9: ذكور | M9: اناث | N9: اجمالي | O9: شعب | P9: ذكور | Q9: اناث | R9: اجمالي | S9: شعب | T9: ذكور | U9: اناث | V9: اجمالي | W9: شعب | X9: ذكور | Y9: اناث | Z9: اجمالي | AA9: شعب | AB9: ذكور | AC9: اناث | AD9: اجمالي | AE9: شعب | AF9: ذكور | AG9: اناث | AH9: اجمالي | AI9: شعب | AJ9: ذكور | AK9: اناث | AL9: اجمالي | AM9: شعب | AN9: ذكور | AO9: اناث | AP9: اجمالي | AQ9: شعب | AR9: ذكور | AS9: اناث | AT9: اجمالي
D10: 1 | F10: ناجح
F11: راسب
D12: 2 | F12: ناجح
F13: راسب
D14: 3 | F14: ناجح
F15: راسب
D16: 4 | F16: ناجح
F17: راسب
D18: 5 | F18: ناجح
F19: راسب
D20: 6 | F20: ناجح
F21: راسب
D22: 7 | F22: ناجح
F23: راسب
D24: 8 | F24: ناجح
F25: راسب
D26: 9 | F26: ناجح
F27: راسب
D28: 10 | F28: ناجح
F29: راسب
D30: 11 | F30: ناجح
F31: راسب
D32: 12 | F32: ناجح
F33: راسب
D34: 13 | F34: ناجح
F35: راسب
D36: 14 | F36: ناجح
F37: راسب
D38: 15 | F38: ناجح
F39: راسب
D40: 16 | F40: ناجح
F41: راسب
D42: 17 | F42: ناجح
F43: راسب
D44: 18 | F44: ناجح
F45: راسب
D46: 19 | F46: ناجح
...

Sheet   عدد الشعب أساسي مديرية
B12: إجمالي التلاميذ | E12: متوسط | H12: المحافظة
B13: إجمالي | C13: إناث | D13: ذكور | E13: كثافة الشعبة | F13: عدد الشعب | G13: الصفوف
B14: =SUM(C14:D14) -> 0 | E14: =(B14/F14) -> #DIV/0! | G14: الأول أساسي | H14: تعــــــز
B15: =SUM(C15:D15) -> 0 | E15: =(B15/F15) -> #DIV/0! | G15: الثاني أساسي
B16: =SUM(C16:D16) -> 0 | E16: =(B16/F16) -> #DIV/0! | G16: الثالث أساسي
B17: =SUM(C17:D17) -> 0 | E17: =(B17/F17) -> #DIV/0! | G17: الرابع أساسي
B18: =SUM(C18:D18) -> 0 | E18: =(B18/F18) -> #DIV/0! | G18: الخامس أساسي
B19: =SUM(C19:D19) -> 0 | E19: =(B19/F19) -> #DIV/0! | G19: السادس أساسي
B20: =SUM(C20:D20) -> 0 | E20: =(B20/F20) -> #DIV/0! | G20: السابع أساسي
B21: =SUM(C21:D21) -> 0 | E21: =(B21/F21) -> #DIV/0! | G21: الثامن أساسي
B22: =SUM(C22:D22) -> 0 | E22: =(B22/F22) -> #DIV/0! | G22: التاسع أساسي
B23: =SUM(B14:B22) -> 0 | E23: =(B23/F23) -> #DIV/0! | F23: =SUM(F14:F22) -> 0 | G23: إجمالي
B24: =B23/F23 -> #DIV/0! | C24: =C23/F23 -> #DIV/0! | D24: =D23/F23 -> #DIV/0! | E24: نسبة الذكور والاناث الى اجمالي التلاميذ %
B25: رئيس قسم التخطيط والاحصاء | F25: مدير ادارة التربية والتعليم بالمديرية

Sheet عدد الشعب الدراسية ثانوي مديرية
B11: إجمالي التلاميذ | E11: متوسط
B12: إجمالي | C12: إناث | D12: ذكور | E12: كثافة الشعبة | F12: عدد الشعب | G12: الصفوف | H12: المحافظة
E13: =B13/F13 -> #DIV/0! | G13: الاول ثانوي عام | H13: تعـــز
E14: =B14/F14 -> #DIV/0! | G14: الثاني ثانوي علمي
E15: =B15/F15 -> #DIV/0! | G15: الثاني ثانوي ادبي
E16: =B16/F16 -> #DIV/0! | G16: الثالث ثانوي علمي
E17: =B17/F17 -> #DIV/0! | G17: الثالث ثانوي ادبي
B18: =SUM(C18:D18) -> 0 | C18: =SUM(C13:C17) -> 0 | D18: =SUM(D13:D17) -> 0 | E18: =B18/F18 -> #DIV/0! | F18: =SUM(F13:F17) -> 0 | G18: إجمالي
B19: =B18/F18 -> #DIV/0! | C19: =C18/F18 -> #DIV/0! | D19: =D18/F18 -> #DIV/0! | E19: نسبة الذكور والاناث الى اجمالي التلاميذ %
A22: رئيس قسم التخطيط والاحصاء | G22: مدير ادارة التربية والتعليم بالمديرية

Sheet  مديرية عدد المدارس
B12: إجمالي | F12: أساسي / ثانوي | J12: ثانوي | N12: أساسي | R12: الجهة
B13: إجمالي | C13: مختلط | D13: بنات | E13: بنين | F13: إجمالي | G13: مختلط | H13: بنات | I13: بنين | J13: إجمالي | K13: مختلط | L13: بنات | M13: بنين | N13: إجمالي | O13: مختلط | P13: بنات | Q13: بنين | R13: الإشرافية
B14: =SUM(C14:E14) -> 0 | C14: =O14+K14+G14 -> 0 | D14: =P14+L14+H14 -> 0 | E14: =Q14+M14+I14 -> 0 | F14: =SUM(G14:I14) -> 0 | J14: =SUM(K14:M14) -> 0 | N14: =SUM(O14:Q14) -> 0 | R14: حكومي
B15: =SUM(C15:E15) -> 0 | C15: =O15+K15+G15 -> 0 | D15: =P15+L15+H15 -> 0 | E15: =Q15+M15+I15 -> 0 | F15: =SUM(G15:I15) -> 0 | J15: =SUM(K15:M15) -> 0 | N15: =SUM(O15:Q15) -> 0 | R15: اهلي
B16: =SUM(C16:E16) -> 0 | C16: =O16+K16+G16 -> 0 | D16: =P16+L16+H16 -> 0 | E16: =Q16+M16+I16 -> 0 | F16: =SUM(G16:I16) -> 0 | J16: =SUM(K16:M16) -> 0 | N16: =SUM(O16:Q16) -> 0 | R16: تحفيظ قرآن
B17: =E17+D17+C17 -> 0 | C17: =SUM(D17:F17) -> 0 | D17: =SUM(E17:G17) -> 0 | E17: =SUM(F17:H17) -> 0 | F17: =SUM(G17:I17) -> 0 | G17: =SUM(H17:J17) -> 0 | H17: =SUM(I17:K17) -> 0 | I17: =SUM(J17:L17) -> 0 | J17: =SUM(K17:M17) -> 0 | ... O17: =SUM(P17:R17) -> 0 | P17: =SUM(P14:P16) -> 0 | Q17: =SUM(Q14:Q16) -> 0 | R17: الإجمالي
D20: مدير ادارة التربية والتعليم بالمديرية | O20: رئيس قسم التخطيط والاحصاء

Sheet احصائية عامة بعدد المدارس
B3: م | C3: اسم المديرية | D3: مدارس حكومي | G3: اجمالي حكومي | H3: مدارس تحفيظ | J3: اجمالى تحفيظ | K3: مدارس اهلية | N3: اجمالي مدارس أهلية | O3: رياض أطفال / حكومي | P3: رياض أطفال/ أهلي | Q3: إجمالي
D4: اساسي | E4: اساسي ثانوي | F4: ثانوي | H4: اولي | I4: تكميلي | K4: اساسي | L4: اساسي ثانوي | M4: ثانوي

Sheet م المؤهلات الدراسية للمعلمين
A7: م | B7: اسم المدرسة | C7: د معلمين | E7: ثانوية | G7: د/بعد الثانوية | I7: بك/ تربية | K7: بك/هندسة | M7: ليسانس آداب | O7: ليسانس شريعة | Q7: بك/تجارة | S7: ماجستير ودكتوراه | U7: اخصائي | W7: اخرى | Y7: إجمالي | AA7: الاجمالي
C8: ذ | D8: ث | E8: ذ | F8: ث | G8: ذ | H8: ث | I8: ذ | J8: ث | K8: ذ | L8: ث | M8: ذ | N8: ث | O8: ذ | P8: ث | Q8: ذ | R8: ث | S8: ذ | T8: ث | U8: ذ | V8: ث | W8: ذ | X8: ث | Y8: ذ | Z8: ث
A9: 1
A10: 2
A11: 3
A12: 4
A13: 5
A14: 6
A15: 7
A16: 8
A17: 9
A18: 10
A19: 11
A20: 12
... A31: 23
A32: الاجمالي
C34: رئيس قسم التخطيط والاحصاء | S34: مدير ادارة التربية والتعليم بالمديرية

Sheet تخصصات المعلمين اساسي
A8: م | B8: اسم المدرسة | C8: رياض اطفال | E8: نهج قراءة | G8: المربين | I8: قرآن | K8: إسلامية | M8: عربي | O8: إنجليزي | Q8: رياضيات | S8: علوم | U8: اجتماعيات | W8: رياضة | Y8: اخصائي | AA8: اخرى | AC8: اجمالي | AE8: الاجمالي
C9: ذ | D9: ث | E9: ذ | F9: ث | G9: ذ | H9: ث | I9: ذ | J9: ث | K9: ذ | L9: ث | M9: ذ | N9: ث | O9: ذ | P9: ث | Q9: ذ | R9: ث | S9: ذ | T9: ث | U9: ذ | V9: ث | W9: ذ | X9: ث | Y9: ذ | Z9: ث | AA9: ذ | AB9: ث | AC9: ذ | AD9: ث
A10: 1
A11: 2
A12: 3
A13: 4
A14: 5
A15: 6
A16: 7
A17: 8
A18: 9
A19: 10
A20: 11
A21: 12
... A32: 23
A33: الاجمالي
C35: رئيس قسم التخطيط والاحصاء | W35: مدير ادارة التربية والتعليم بالمديرية

Sheet تخصصات المعلمين ثانوي
A8: م | B8: اسم المدرسة | C8: قرآن | E8: إسلامية | G8: عربي | I8: إنجليزي | K8: رياضيات | M8: فيزياء | O8: كيمياء | Q8: أحياء | S8: جغرافيا | U8: تاريخ | W8: مجتمع | Y8: مواد فلسفية | AA8: احصائي | AC8: رياضة | AE8: فرنسي | AG8: حاسوب | AI8: اخرى | AK8: اجمالي | AM8: الاجمالي
C9: ذ | D9: ث | E9: ذ | F9: ث | G9: ذ | H9: ث | I9: ذ | J9: ث | K9: ذ | L9: ث | M9: ذ | N9: ث | O9: ذ | P9: ث | Q9: ذ | R9: ذ | S9: ذ | T9: ث | U9: ذ | V9: ث | W9: ذ | X9: ث | Y9: ذ | Z9: ث | AA9: ذ | AB9: ث | AC9: ذ | AD9: ث | AE9: ذ | AF9: ث | AG9: ذ | AH9: ث | AI9: ذ | AJ9: ث | AK9: ذ | AL9: ث
A10: 1
A11: 2
A12: 3
A13: 4
A14: 5
A15: 6
A16: 7
A17: 8
A18: 9
A19: 10
A20: 11
A21: 12
... A32: 23
A33: الاجمالي
C35: رئيس قسم التخطيط والاحصاء | AB35: مدير ادارة التربية والتعليم بالمديرية

Sheet قوى عاملة أساسي مديرية
A4: م | B4: اسم المدرسة | C4: مدير | E4: وكيل | G4: م / اداري | I4: م/أنشطة | K4: م/ صحي | M4: م/ وسيائل | O4: خ/ إجتماعي | Q4: أ /معمل | S4: أ /مكتبة | U4: أ / مخزن | W4: مدرس | Y4: عامل | AA4: حارس | AC4: اخرى | AE4: الإجمالي
C5: ذ | D5: ث | E5: ذ | F5: ث | G5: ذ | H5: ث | I5: ذ | J5: ث | K5: ذ | L5: ث | M5: ذ | N5: ث | O5: ذ | P5: ث | Q5: ذ | R5: ث | S5: ذ | T5: ث | U5: ذ | V5: ث | W5: ذ | X5: ث | Y5: ذ | Z5: ث | AA5: ذ | AB5: ث | AC5: ذ | AD5: ث | AE5: ذ | AF5: ث | AG5: ج
A6: 1 | AE6: =SUM(Y6,AC6,AA6,W6,U6,S6,Q6,O6,M6,K6,I6,G6,E6,C6) -> 0 | AF6: =SUM(Z6,AD6,AB6,X6,V6,T6,R6,P6,N6,L6,J6,H6,F6,D6) -> 0 | AG6: =SUM(AE6,AF6) -> 0
A7: 2 | AE7: =SUM(Y7,AC7,AA7,W7,U7,S7,Q7,O7,M7,K7,I7,G7,E7,C7) -> 0 | AF7: =SUM(Z7,AD7,AB7,X7,V7,T7,R7,P7,N7,L7,J7,H7,F7,D7) -> 0 | AG7: =SUM(AE7,AF7) -> 0
A8: 3 | AE8: =SUM(Y8,AC8,AA8,W8,U8,S8,Q8,O8,M8,K8,I8,G8,E8,C8) -> 0 | AF8: =SUM(Z8,AD8,AB8,X8,V8,T8,R8,P8,N8,L8,J8,H8,F8,D8) -> 0 | AG8: =SUM(AE8,AF8) -> 0
A9: 4 | AE9: =SUM(Y9,AC9,AA9,W9,U9,S9,Q9,O9,M9,K9,I9,G9,E9,C9) -> 0 | AF9: =SUM(Z9,AD9,AB9,X9,V9,T9,R9,P9,N9,L9,J9,H9,F9,D9) -> 0 | AG9: =SUM(AE9,AF9) -> 0
A10: 5 | AE10: =SUM(Y10,AC10,AA10,W10,U10,S10,Q10,O10,M10,K10,I10,G10,E10,C10) -> 0 | AF10: =SUM(Z10,AD10,AB10,X10,V10,T10,R10,P10,N10,L10,J10,H10,F10,D10) -> 0 | AG10: =SUM(AE10,AF10) -> 0
A11: 6 | AE11: =SUM(Y11,AC11,AA11,W11,U11,S11,Q11,O11,M11,K11,I11,G11,E11,C11) -> 0 | AF11: =SUM(Z11,AD11,AB11,X11,V11,T11,R11,P11,N11,L11,J11,H11,F11,D11) -> 0 | AG11: =SUM(AE11,AF11) -> 0
A12: 7 | AE12: =SUM(Y12,AC12,AA12,W12,U12,S12,Q12,O12,M12,K12,I12,G12,E12,C12) -> 0 | AF12: =SUM(Z12,AD12,AB12,X12,V12,T12,R12,P12,N12,L12,J12,H12,F12,D12) -> 0 | AG12: =SUM(AE12,AF12) -> 0
A13: 8 | AE13: =SUM(Y13,AC13,AA13,W13,U13,S13,Q13,O13,M13,K13,I13,G13,E13,C13) -> 0 | AF13: =SUM(Z13,AD13,AB13,X13,V13,T13,R13,P13,N13,L13,J13,H13,F13,D13) -> 0 | AG13: =SUM(AE13,AF13) -> 0
A14: 9 | AE14: =SUM(Y14,AC14,AA14,W14,U14,S14,Q14,O14,M14,K14,I14,G14,E14,C14) -> 0 | AF14: =SUM(Z14,AD14,AB14,X14,V14,T14,R14,P14,N14,L14,J14,H14,F14,D14) -> 0 | AG14: =SUM(AE14,AF14) -> 0
A15: 10 | AE15: =SUM(Y15,AC15,AA15,W15,U15,S15,Q15,O15,M15,K15,I15,G15,E15,C15) -> 0 | AF15: =SUM(Z15,AD15,AB15,X15,V15,T15,R15,P15,N15,L15,J15,H15,F15,D15) -> 0 | AG15: =SUM(AE15,AF15) -> 0
A16: 11 | AE16: =SUM(Y16,AC16,AA16,W16,U16,S16,Q16,O16,M16,K16,I16,G16,E16,C16) -> 0 | AF16: =SUM(Z16,AD16,AB16,X16,V16,T16,R16,P16,N16,L16,J16,H16,F16,D16) -> 0 | AG16: =SUM(AE16,AF16) -> 0
A17: 12 | AE17: =SUM(Y17,AC17,AA17,W17,U17,S17,Q17,O17,M17,K17,I17,G17,E17,C17) -> 0 | AF17: =SUM(Z17,AD17,AB17,X17,V17,T17,R17,P17,N17,L17,J17,H17,F17,D17) -> 0 | AG17: =SUM(AE17,AF17) -> 0
... A25: 20 | AE25: =SUM(Y25,AC25,AA25,W25,U25,S25,Q25,O25,M25,K25,I25,G25,E25,C25) -> 0 | AF25: =SUM(Z25,AD25,AB25,X25,V25,T25,R25,P25,N25,L25,J25,H25,F25,D25) -> 0 | AG25: =SUM(AE25,AF25) -> 0
A26: الاجمالي | C26: =SUM(C6:C25) -> 0 | D26: =SUM(D6:D25) -> 0 | E26: =SUM(E6:E25) -> 0 | F26: =SUM(F6:F25) -> 0 | G26: =SUM(G6:G25) -> 0 | H26: =SUM(H6:H25) -> 0 | I26: =SUM(I6:I25) -> 0 | J26: =SUM(J6:J25) -> 0 | ... AG26: =SUM(AG6:AG25) -> 0
F28: رئيس قسم التخطيط والاحصاء | W28: مدير ادارة التربية والتعليم بالمديرية

Sheet قوى عاملة ثانوي مديرية 
A5: م | B5: اسم المدرسة | C5: مدير | E5: وكيل | G5: مشرف إداري | I5: مشرف أنشطة | K5: مشرف صحي | M5: مشرف وسيلة | O5: مشرف إجتماعي | Q5: أمين معمل | S5: امين مخزن | U5: امين مكتبة | W5: مدرس | Y5: حارس | AA5: عمال | AC5: أشياء أخرى | AE5: الإجمالي
C6: ذ | D6: ث | E6: ذ | F6: ث | G6: ذ | H6: ث | I6: ذ | J6: ث | K6: ذ | L6: ث | M6: ذ | N6: ث | O6: ذ | P6: ث | Q6: ذ | R6: ث | S6: ذ | T6: ث | U6: ذ | V6: ث | W6: ذ | X6: ث | Y6: ذ | Z6: ث | AA6: ذ | AB6: ث | AC6: ذ | AD6: ث | AE6: ذ | AF6: ث | AG6: ج
A7: 1 | AE7: =SUM(AC7,AA7,Y7,W7,U7,S7,Q7,M7,K7,I7,G7,E7,C7) -> 0 | AF7: =SUM(AD7,AB7,Z7,X7,V7,T7,R7,N7,L7,J7,H7,F7,D7) -> 0 | AG7: =SUM(AE7:AF7) -> 0
A8: 2 | AE8: =SUM(AC8,AA8,Y8,W8,U8,S8,Q8,M8,K8,I8,G8,E8,C8) -> 0 | AF8: =SUM(AD8,AB8,Z8,X8,V8,T8,R8,N8,L8,J8,H8,F8,D8) -> 0 | AG8: =SUM(AE8:AF8) -> 0
A9: 3 | AE9: =SUM(AC9,AA9,Y9,W9,U9,S9,Q9,M9,K9,I9,G9,E9,C9) -> 0 | AF9: =SUM(AD9,AB9,Z9,X9,V9,T9,R9,N9,L9,J9,H9,F9,D9) -> 0 | AG9: =SUM(AE9:AF9) -> 0
A10: 4 | AE10: =SUM(AC10,AA10,Y10,W10,U10,S10,Q10,M10,K10,I10,G10,E10,C10) -> 0 | AF10: =SUM(AD10,AB10,Z10,X10,V10,T10,R10,N10,L10,J10,H10,F10,D10) -> 0 | AG10: =SUM(AE10:AF10) -> 0
A11: 5 | AE11: =SUM(AC11,AA11,Y11,W11,U11,S11,Q11,M11,K11,I11,G11,E11,C11) -> 0 | AF11: =SUM(AD11,AB11,Z11,X11,V11,T11,R11,N11,L11,J11,H11,F11,D11) -> 0 | AG11: =SUM(AE11:AF11) -> 0
A12: 6 | AE12: =SUM(AC12,AA12,Y12,W12,U12,S12,Q12,M12,K12,I12,G12,E12,C12) -> 0 | AF12: =SUM(AD12,AB12,Z12,X12,V12,T12,R12,N12,L12,J12,H12,F12,D12) -> 0 | AG12: =SUM(AE12:AF12) -> 0
A13: 7 | AE13: =SUM(AC13,AA13,Y13,W13,U13,S13,Q13,M13,K13,I13,G13,E13,C13) -> 0 | AF13: =SUM(AD13,AB13,Z13,X13,V13,T13,R13,N13,L13,J13,H13,F13,D13) -> 0 | AG13: =SUM(AE13:AF13) -> 0
A14: 8 | AE14: =SUM(AC14,AA14,Y14,W14,U14,S14,Q14,M14,K14,I14,G14,E14,C14) -> 0 | AF14: =SUM(AD14,AB14,Z14,X14,V14,T14,R14,N14,L14,J14,H14,F14,D14) -> 0 | AG14: =SUM(AE14:AF14) -> 0
A15: 9 | AE15: =SUM(AC15,AA15,Y15,W15,U15,S15,Q15,M15,K15,I15,G15,E15,C15) -> 0 | AF15: =SUM(AD15,AB15,Z15,X15,V15,T15,R15,N15,L15,J15,H15,F15,D15) -> 0 | AG15: =SUM(AE15:AF15) -> 0
A16: 10 | AE16: =SUM(AC16,AA16,Y16,W16,U16,S16,Q16,M16,K16,I16,G16,E16,C16) -> 0 | AF16: =SUM(AD16,AB16,Z16,X16,V16,T16,R16,N16,L16,J16,H16,F16,D16) -> 0 | AG16: =SUM(AE16:AF16) -> 0
A17: 11 | AE17: =SUM(AC17,AA17,Y17,W17,U17,S17,Q17,M17,K17,I17,G17,E17,C17) -> 0 | AF17: =SUM(AD17,AB17,Z17,X17,V17,T17,R17,N17,L17,J17,H17,F17,D17) -> 0 | AG17: =SUM(AE17:AF17) -> 0
A18: 12 | AE18: =SUM(AC18,AA18,Y18,W18,U18,S18,Q18,M18,K18,I18,G18,E18,C18) -> 0 | AF18: =SUM(AD18,AB18,Z18,X18,V18,T18,R18,N18,L18,J18,H18,F18,D18) -> 0 | AG18: =SUM(AE18:AF18) -> 0
... A26: 20 | AE26: =SUM(AC26,AA26,Y26,W26,U26,S26,Q26,M26,K26,I26,G26,E26,C26) -> 0 | AF26: =SUM(AD26,AB26,Z26,X26,V26,T26,R26,N26,L26,J26,H26,F26,D26) -> 0 | AG26: =SUM(AE26:AF26) -> 0
A27: الإجمالي | C27: =SUM(C7:C26) -> 0 | D27: =SUM(D7:D26) -> 0 | E27: =SUM(E7:E26) -> 0 | F27: =SUM(F7:F26) -> 0 | G27: =SUM(G7:G26) -> 0 | H27: =SUM(H7:H26) -> 0 | I27: =SUM(I7:I26) -> 0 | J27: =SUM(J7:J26) -> 0 | ... AG27: =SUM(AG7:AG26) -> 0
F30: رئيس قسم التخطيط والاحصاء | V30: مدير ادارة التربية والتعليم بالمديرية

Sheet مديرية معلمين اساسي
A8: م | B8: اسم المدرسة | C8: ذكور | D8: إناث | E8: الاجمالي
A10: 1 | C10: ='قوى عاملة تحفيظ أولي وتكميلي'!G6 -> 0 | D10: ='قوى عاملة تحفيظ أولي وتكميلي'!H6 -> 0 | E10: =SUM(C10:D10) -> 0
A11: 2 | C11: ='قوى عاملة تحفيظ أولي وتكميلي'!G7 -> 0 | D11: ='قوى عاملة تحفيظ أولي وتكميلي'!H7 -> 0 | E11: =SUM(C11:D11) -> 0
A12: 3 | C12: ='قوى عاملة تحفيظ أولي وتكميلي'!G8 -> 0 | D12: ='قوى عاملة تحفيظ أولي وتكميلي'!H8 -> 0 | E12: =SUM(C12:D12) -> 0
A13: 4 | C13: ='قوى عاملة تحفيظ أولي وتكميلي'!G9 -> 0 | D13: ='قوى عاملة تحفيظ أولي وتكميلي'!H9 -> 0 | E13: =SUM(C13:D13) -> 0
A14: 5 | C14: ='قوى عاملة تحفيظ أولي وتكميلي'!G10 -> 0 | D14: ='قوى عاملة تحفيظ أولي وتكميلي'!H10 -> 0 | E14: =SUM(C14:D14) -> 0
A15: 6 | C15: ='قوى عاملة تحفيظ أولي وتكميلي'!G11 -> 0 | D15: ='قوى عاملة تحفيظ أولي وتكميلي'!H11 -> 0 | E15: =SUM(C15:D15) -> 0
A16: 7 | C16: ='قوى عاملة تحفيظ أولي وتكميلي'!G12 -> 0 | D16: ='قوى عاملة تحفيظ أولي وتكميلي'!H12 -> 0 | E16: =SUM(C16:D16) -> 0
A17: 8 | C17: ='قوى عاملة تحفيظ أولي وتكميلي'!G13 -> 0 | D17: ='قوى عاملة تحفيظ أولي وتكميلي'!H13 -> 0 | E17: =SUM(C17:D17) -> 0
A18: 9 | C18: ='قوى عاملة تحفيظ أولي وتكميلي'!G14 -> 0 | D18: ='قوى عاملة تحفيظ أولي وتكميلي'!H14 -> 0 | E18: =SUM(C18:D18) -> 0
A19: 10 | C19: ='قوى عاملة تحفيظ أولي وتكميلي'!G15 -> 0 | D19: ='قوى عاملة تحفيظ أولي وتكميلي'!H15 -> 0 | E19: =SUM(C19:D19) -> 0
A20: 11 | C20: ='قوى عاملة تحفيظ أولي وتكميلي'!G16 -> 0 | D20: ='قوى عاملة تحفيظ أولي وتكميلي'!H16 -> 0 | E20: =SUM(C20:D20) -> 0
A21: 12 | C21: ='قوى عاملة تحفيظ أولي وتكميلي'!G17 -> 0 | D21: ='قوى عاملة تحفيظ أولي وتكميلي'!H17 -> 0 | E21: =SUM(C21:D21) -> 0
... A23: 14 | C23: ='قوى عاملة تحفيظ أولي وتكميلي'!G19 -> 0 | D23: ='قوى عاملة تحفيظ أولي وتكميلي'!H19 -> 0 | E23: =SUM(C23:D23) -> 0
A24: 15 | C24: ='قوى عاملة تحفيظ أولي وتكميلي'!G25 -> 0 | D24: ='قوى عاملة تحفيظ أولي وتكميلي'!H25 -> 0 | E24: =SUM(C24:D24) -> 0
A25: 16 | E25: =SUM(C25:D25) -> 0
A26: 17 | E26: =SUM(C26:D26) -> 0
A27: 18 | E27: =SUM(C27:D27) -> 0
A28: 19 | E28: =SUM(C28:D28) -> 0
A29: 20 | E29: =SUM(C29:D29) -> 0
A30: الاجمالي | C30: =SUM(C10:C29) -> 0 | D30: =SUM(D10:D29) -> 0 | E30: =SUM(E10:E29) -> 0

Sheet معلمين  ثانوي مديرية)
A9: م | B9: اسم المدرسة | C9: ذكور | D9: إناث | E9: الاجمالي
A11: 1 | C11: ='قوى عاملة تحفيظ أولي وتكميلي'!G6 -> 0 | D11: ='قوى عاملة تحفيظ أولي وتكميلي'!H6 -> 0 | E11: =SUM(C11:D11) -> 0
A12: 2 | C12: ='قوى عاملة تحفيظ أولي وتكميلي'!G7 -> 0 | D12: ='قوى عاملة تحفيظ أولي وتكميلي'!H7 -> 0 | E12: =SUM(C12:D12) -> 0
A13: 3 | C13: ='قوى عاملة تحفيظ أولي وتكميلي'!G8 -> 0 | D13: ='قوى عاملة تحفيظ أولي وتكميلي'!H8 -> 0 | E13: =SUM(C13:D13) -> 0
A14: 4 | C14: ='قوى عاملة تحفيظ أولي وتكميلي'!G9 -> 0 | D14: ='قوى عاملة تحفيظ أولي وتكميلي'!H9 -> 0 | E14: =SUM(C14:D14) -> 0
A15: 5 | C15: ='قوى عاملة تحفيظ أولي وتكميلي'!G10 -> 0 | D15: ='قوى عاملة تحفيظ أولي وتكميلي'!H10 -> 0 | E15: =SUM(C15:D15) -> 0
A16: 6 | C16: ='قوى عاملة تحفيظ أولي وتكميلي'!G11 -> 0 | D16: ='قوى عاملة تحفيظ أولي وتكميلي'!H11 -> 0 | E16: =SUM(C16:D16) -> 0
A17: 7 | C17: ='قوى عاملة تحفيظ أولي وتكميلي'!G12 -> 0 | D17: ='قوى عاملة تحفيظ أولي وتكميلي'!H12 -> 0 | E17: =SUM(C17:D17) -> 0
A18: 8 | C18: ='قوى عاملة تحفيظ أولي وتكميلي'!G13 -> 0 | D18: ='قوى عاملة تحفيظ أولي وتكميلي'!H13 -> 0 | E18: =SUM(C18:D18) -> 0
A19: 9 | C19: ='قوى عاملة تحفيظ أولي وتكميلي'!G14 -> 0 | D19: ='قوى عاملة تحفيظ أولي وتكميلي'!H14 -> 0 | E19: =SUM(C19:D19) -> 0
A20: 10 | C20: ='قوى عاملة تحفيظ أولي وتكميلي'!G15 -> 0 | D20: ='قوى عاملة تحفيظ أولي وتكميلي'!H15 -> 0 | E20: =SUM(C20:D20) -> 0
A21: 11 | C21: ='قوى عاملة تحفيظ أولي وتكميلي'!G16 -> 0 | D21: ='قوى عاملة تحفيظ أولي وتكميلي'!H16 -> 0 | E21: =SUM(C21:D21) -> 0
A22: 12 | C22: ='قوى عاملة تحفيظ أولي وتكميلي'!G17 -> 0 | D22: ='قوى عاملة تحفيظ أولي وتكميلي'!H17 -> 0 | E22: =SUM(C22:D22) -> 0
... A24: 14 | C24: ='قوى عاملة تحفيظ أولي وتكميلي'!G19 -> 0 | D24: ='قوى عاملة تحفيظ أولي وتكميلي'!H19 -> 0 | E24: =SUM(C24:D24) -> 0
A25: 15 | C25: ='قوى عاملة تحفيظ أولي وتكميلي'!G25 -> 0 | D25: ='قوى عاملة تحفيظ أولي وتكميلي'!H25 -> 0 | E25: =SUM(C25:D25) -> 0
A26: 16 | C26: ='قوى عاملة تحفيظ أولي وتكميلي'!#REF! -> #REF! | D26: ='قوى عاملة تحفيظ أولي وتكميلي'!#REF! -> #REF! | E26: =SUM(C26:D26) -> #REF!
A27: 17 | C27: ='قوى عاملة تحفيظ أولي وتكميلي'!#REF! -> #REF! | D27: ='قوى عاملة تحفيظ أولي وتكميلي'!#REF! -> #REF! | E27: =SUM(C27:D27) -> #REF!
A28: 18 | C28: ='قوى عاملة تحفيظ أولي وتكميلي'!#REF! -> #REF! | D28: ='قوى عاملة تحفيظ أولي وتكميلي'!#REF! -> #REF! | E28: =SUM(C28:D28) -> #REF!
A29: 19 | C29: ='قوى عاملة تحفيظ أولي وتكميلي'!#REF! -> #REF! | D29: ='قوى عاملة تحفيظ أولي وتكميلي'!#REF! -> #REF! | E29: =SUM(C29:D29) -> #REF!
A30: 20 | C30: ='قوى عاملة تحفيظ أولي وتكميلي'!#REF! -> #REF! | D30: ='قوى عاملة تحفيظ أولي وتكميلي'!#REF! -> #REF! | E30: =SUM(C30:D30) -> #REF!
A31: الاجمالي | C31: =SUM(C11:C30) -> #REF! | D31: =SUM(D11:D30) -> #REF! | E31: =SUM(E11:E30) -> #REF!

Sheet احصائية بموظفي المديرية
A4: م | B4: اموظفي المديرية | C4: ذكور | D4: إناث | E4: الاجمالي
A6: 1 | B6: المدير ـ النواب | E6: =SUM(C6:D6) -> 0
A7: 2 | B7: سكرتارية المديرية | E7: =SUM(C7:D7) -> 0
A8: 3 | B8: قسم التعليم | E8: =SUM(C8:D8) -> 0
A9: 4 | B9: قسم االتخطيط والاحصاء | E9: =SUM(C9:D9) -> 0
A10: 5 | B10: قسم المشاريع | E10: =SUM(C10:D10) -> 0
A11: 6 | B11: قسم الموارد | E11: =SUM(C11:D11) -> 0
A12: 7 | B12: قسم التوجيه | E12: =SUM(C12:D12) -> 0
A13: 8 | B13: فسم الرقابة | E13: =SUM(C13:D13) -> 0
A14: 9 | B14: قسم الاختبارات | E14: =SUM(C14:D14) -> 0
A15: 10 | B15: قسم النظم | E15: =SUM(C15:D15) -> 0
A16: 11 | B16: قسم الرقابة | E16: =SUM(C16:D16) -> 0
A17: 12 | B17: قسم تعليم الفتاة | E17: =SUM(C17:D17) -> 0
... A29: 24 | B29: قسم الصحة المدرسية | E29: =SUM(C29:D29) -> 0
E30: =SUM(C30:D30) -> 0
A31: الاجمالي | C31: =SUM(C6:C30) -> 0 | D31: =SUM(D6:D30) -> 0 | E31: =SUM(E6:E30) -> 0
B35: قسم التخطيط والإحصاء | D35: مدير إدارة التربية والتعليم في المديرية

Sheet الموجهين 
A3: اسم المديرية | B3: التوجيه الفني | D3: رقابة وتقتيش | F3: انشطة مدرسية | H3: المتابعة | J3: إجمالي | L3: إجمالي عام
B4: ذكور | C4: إناث | D4: ذكور | E4: إناث | F4: ذكور | G4: إناث | H4: ذكور | I4: إناث | J4: ذكور | K4: إناث
B8: رئيس قسم التخطيط والاحصاء | I8: مدير ادارة التربية والتعليم في المديرية

Sheet رياض اطفال  الطلبه والمربي حكوم
B5: م | C5: اسم المدرسة/ الروضة | D5: عدد الطلبة | F5: إجمالي الطلبة | G5: عدد المعلمين | I5: الإجمالي المعلمين
D6: ذكور | E6: إناث | G6: ذكور | H6: إناث
B8: 1 | F8: =D8+E8 -> 0 | I8: =G8+H8 -> 0
B9: 2 | F9: =D9+E9 -> 0 | I9: =G9+H9 -> 0
B10: 3 | F10: =D10+E10 -> 0 | I10: =G10+H10 -> 0
B11: 4 | F11: =D11+E11 -> 0 | I11: =G11+H11 -> 0
B12: 5 | F12: =D12+E12 -> 0 | I12: =G12+H12 -> 0
B13: 6 | F13: =D13+E13 -> 0 | I13: =G13+H13 -> 0
B14: 7 | F14: =D14+E14 -> 0 | I14: =G14+H14 -> 0
B15: 8 | F15: =D15+E15 -> 0 | I15: =G15+H15 -> 0
B16: 9 | F16: =D16+E16 -> 0 | I16: =G16+H16 -> 0
B17: 10 | F17: =D17+E17 -> 0 | I17: =G17+H17 -> 0
B18: 11 | F18: =D18+E18 -> 0 | I18: =G18+H18 -> 0
B19: 12 | F19: =D19+E19 -> 0 | I19: =G19+H19 -> 0
... B27: 20 | F27: =D27+E27 -> 0 | I27: =G27+H27 -> 0
B28: الاجمالي | D28: =SUM(D8:D27) -> 0 | E28: =SUM(E8:E27) -> 0 | F28: =D28+E28 -> 0 | G28: =SUM(G8:G27) -> 0 | H28: =SUM(H8:H27) -> 0 | I28: =SUM(I8:I27) -> 0
B30: رئيس قسم التخطيط والاحصاء | E30: مدير ادارة التربية والتعليم بالمديرية

Sheet رياض اطفال  الطلبه والمربي أهلي
B5: م | C5: اسم المدرسة/ الروضة | D5: عدد الطلبة | F5: إجمالي الطلبة | G5: عدد المعلمين | I5: الإجمالي المعلمين
D6: ذكور | E6: إناث | G6: ذكور | H6: إناث
B8: 1 | F8: =D8+E8 -> 0 | I8: =G8+H8 -> 0
B9: 2 | F9: =D9+E9 -> 0 | I9: =G9+H9 -> 0
B10: 3 | F10: =D10+E10 -> 0 | I10: =G10+H10 -> 0
B11: 4 | F11: =D11+E11 -> 0 | I11: =G11+H11 -> 0
B12: 5 | F12: =D12+E12 -> 0 | I12: =G12+H12 -> 0
B13: 6 | F13: =D13+E13 -> 0 | I13: =G13+H13 -> 0
B14: 7 | F14: =D14+E14 -> 0 | I14: =G14+H14 -> 0
B15: 8 | F15: =D15+E15 -> 0 | I15: =G15+H15 -> 0
B16: 9 | F16: =D16+E16 -> 0 | I16: =G16+H16 -> 0
B17: 10 | F17: =D17+E17 -> 0 | I17: =G17+H17 -> 0
B18: 11 | F18: =D18+E18 -> 0 | I18: =G18+H18 -> 0
B19: 12 | F19: =D19+E19 -> 0 | I19: =G19+H19 -> 0
... B27: 20 | F27: =D27+E27 -> 0 | I27: =G27+H27 -> 0
B28: الاجمالي | D28: =SUM(D8:D27) -> 0 | E28: =SUM(E8:E27) -> 0 | F28: =D28+E28 -> 0 | G28: =SUM(G8:G27) -> 0 | H28: =SUM(H8:H27) -> 0 | I28: =SUM(I8:I27) -> 0
B30: رئيس قسم التخطيط والاحصاء | E30: مدير ادارة التربية والتعليم بالمديرية

Sheet  حكومي  مكونات المبنى المدرسي
A7: إحصائيات توضح مكونات المبنى المدرسي في المدارس العاملة وبحسب المرحلة الدراسية حكومي
A8: مديرية.......................للعام الدراسي 2025 - 2026 م
A9: مكونات المبنى المدرسي
A10: مبنى مدرسي | B10: عمارة | C10: أخرى تذكر | D10: عدد الغرف المدرسية في المبنى | G10: صلاحية الغرف الدراسية | J10: الغرف الدراسيسة فقط | K10: إدارة المدرسة | M10: استراحة مدرسين | O10: مسرح/ محتوياته | Q10: عدد الحمامات | S10: سور المدرسة يحيط بها | U10: كهرباء حكومي/ أهلي | W10: المياه | Y10: مقصف | AA10: طريق سيارة | AC10: اسم المدرسة
D11: أساسي | E11: ثانوي | F11: إجمالي | G11: صالح | H11: يحتاج ترميم | I11: غير صالح | K11: يوجد | L11: لا يوجد | M11: يوجد | N11: لا يوجد | O11: يوجد | P11: لا يوجد | Q11: صالحة | R11: غير صالحة | S11: يوجد | T11: لا يوجد | U11: شاشة تلفزيون | V11: منظومة طاقة | W11: يوجد | X11: لا يوجد | Y11: يوجد | Z11: لا يوجد | AA11: يوجد | AB11: لا يوجد
B17: مدير المدرسة | L17: رئيس قسم التخطيط والاحصاء | V17: مدير ادارة التربية والتعليم بالمديرية

Sheet اساسي من 6-9
C1: الجمهورية اليمنية
C2: وزارة التربية والتعليم / العاصمة عدن
C3: الإدارة العامة للإحصاء والتخطيط
B7: م | C7: اسم المدرسة | D7: عدد | E7: عدد | F7: الصف السادس | J7: الصف السابع | N7: الصف الثامن | R7: الصف التاسع | V7: اجمالي عام (1 - 9)
D8: المدارس | E8: المديريات | F8: شعب | G8: ذكور | H8: إناث | I8: الإجمالي | J8: شعب | K8: ذكور | L8: إناث | M8: الإجمالي | N8: شعب | O8: ذكور | P8: إناث | Q8: الإجمالي | R8: شعب | S8: ذكور | T8: إناث | U8: الإجمالي | V8: شعب | W8: ذكور | X8: إناث | Y8: الإجمالي
B9: 1 | C9: القاهرة | I9: =SUM(G9:H9) -> 0 | M9: =SUM(K9:L9) -> 0 | Q9: =SUM(O9:P9) -> 0 | U9: =SUM(S9:T9) -> 0 | Y9: =SUM(W9:X9) -> 0
B10: 2 | C10: المظفر | I10: =SUM(G10:H10) -> 0 | M10: =SUM(K10:L10) -> 0 | Q10: =SUM(O10:P10) -> 0 | U10: =SUM(S10:T10) -> 0 | Y10: =SUM(W10:X10) -> 0
B11: 3 | C11: صالة | I11: =SUM(G11:H11) -> 0 | M11: =SUM(K11:L11) -> 0 | Q11: =SUM(O11:P11) -> 0 | U11: =SUM(S11:T11) -> 0 | Y11: =SUM(W11:X11) -> 0
B12: 4 | C12: الموادم | I12: =SUM(G12:H12) -> 0 | M12: =SUM(K12:L12) -> 0 | Q12: =SUM(O12:P12) -> 0 | U12: =SUM(S12:T12) -> 0 | Y12: =SUM(W12:X12) -> 0
B13: 5 | C13: مشرعة | I13: =SUM(G13:H13) -> 0 | M13: =SUM(K13:L13) -> 0 | Q13: =SUM(O13:P13) -> 0 | U13: =SUM(S13:T13) -> 0 | Y13: =SUM(W13:X13) -> 0
B14: 6 | C14: جبل حبشي | I14: =SUM(G14:H14) -> 0 | M14: =SUM(K14:L14) -> 0 | Q14: =SUM(O14:P14) -> 0 | U14: =SUM(S14:T14) -> 0 | Y14: =SUM(W14:X14) -> 0
B15: 7 | C15: المسراخ | I15: =SUM(G15:H15) -> 0 | M15: =SUM(K15:L15) -> 0 | Q15: =SUM(O15:P15) -> 0 | U15: =SUM(S15:T15) -> 0 | Y15: =SUM(W15:X15) -> 0
B16: 8 | C16: الشمايتين | I16: =SUM(G16:H16) -> 0 | M16: =SUM(K16:L16) -> 0 | Q16: =SUM(O16:P16) -> 0 | U16: =SUM(S16:T16) -> 0 | Y16: =SUM(W16:X16) -> 0
B17: 9 | C17: المعافر | I17: =SUM(G17:H17) -> 0 | M17: =SUM(K17:L17) -> 0 | Q17: =SUM(O17:P17) -> 0 | U17: =SUM(S17:T17) -> 0 | Y17: =SUM(W17:X17) -> 0
B18: 10 | C18: المواسط | I18: =SUM(G18:H18) -> 0 | M18: =SUM(K18:L18) -> 0 | Q18: =SUM(O18:P18) -> 0 | U18: =SUM(S18:T18) -> 0 | Y18: =SUM(W18:X18) -> 0
B19: 11 | C19: سامع | I19: =SUM(G19:H19) -> 0 | M19: =SUM(K19:L19) -> 0 | Q19: =SUM(O19:P19) -> 0 | U19: =SUM(S19:T19) -> 0 | Y19: =SUM(W19:X19) -> 0
B20: 12 | C20: الصلو | I20: =SUM(G20:H20) -> 0 | M20: =SUM(K20:L20) -> 0 | Q20: =SUM(O20:P20) -> 0 | U20: =SUM(S20:T20) -> 0 | Y20: =SUM(W20:X20) -> 0
... B26: 18 | C26: خدير | I26: =SUM(G26:H26) -> 0 | M26: =SUM(K26:L26) -> 0 | Q26: =SUM(O26:P26) -> 0 | U26: =SUM(S26:T26) -> 0 | Y26: =SUM(W26:X26) -> 0
B27: 19 | C27: حيفان | G27: 1056 | H27: 991 | I27: =SUM(G27:H27) -> 2047 | K27: 1101 | L27: 952 | M27: =SUM(K27:L27) -> 2053 | O27: 986 | P27: 839 | Q27: =SUM(O27:P27) -> 1825 | S27: 836 | T27: 810 | U27: =SUM(S27:T27) -> 1646 | W27: 1157 | X27: 995 | Y27: =SUM(W27:X27) -> 2152
B28: 20 | C28: ماوية | I28: =SUM(G28:H28) -> 0 | M28: =SUM(K28:L28) -> 0 | Q28: =SUM(O28:P28) -> 0 | U28: =SUM(S28:T28) -> 0 | Y28: =SUM(W28:X28) -> 0
B29: 21 | C29: التعزية | I29: =SUM(G29:H29) -> 0 | M29: =SUM(K29:L29) -> 0 | Q29: =SUM(O29:P29) -> 0 | U29: =SUM(S29:T29) -> 0 | Y29: =SUM(W29:X29) -> 0
B30: 22 | C30: السلام | I30: =SUM(G30:H30) -> 0 | M30: =SUM(K30:L30) -> 0 | Q30: =SUM(O30:P30) -> 0 | U30: =SUM(S30:T30) -> 0 | Y30: =SUM(W30:X30) -> 0
B31: 23 | C31: الرونة | I31: =SUM(G31:H31) -> 0 | M31: =SUM(K31:L31) -> 0 | Q31: =SUM(O31:P31) -> 0 | U31: =SUM(S31:T31) -> 0 | Y31: =SUM(W31:X31) -> 0
B32: الإجمالي | D32: =SUM(D9:D31) -> 0 | E32: =SUM(E9:E31) -> 0 | F32: =SUM(F9:F31) -> 0 | G32: =SUM(G9:G31) -> 1056 | H32: =SUM(H9:H31) -> 991 | I32: =SUM(I9:I31) -> 2047 | J32: =SUM(J9:J31) -> 0 | K32: =SUM(K9:K31) -> 1101 | ... Y32: =SUM(Y9:Y31) -> 2152
C34: مدير ادارة الاحصاء والتخطيط | S34: أ/ عبدالواسع شداد
C35: أ/ قائد السامعي | S35: مدير مكب التربية والتعليم

Sheet ورقة1

Sheet طلاب تحفيظ أولي
A4: م | B4: اسم المدرسة | C4: الاولأولي | G4: لثاني أولي | K4: الثالث أولي | O4: الرابع أولي | S4: الخامس أولي | W4: السادس أولي | AA4: السابع أولي | AE4: الثامن أولي | AI4: التاسع أولي | AM4: اجمالي عام (1 - 9)
C5: شعب | D5: ذكور | E5: إناث | F5: الإجمالي | G5: شعب | H5: ذكور | I5: إناث | J5: الإجمالي | K5: شعب | L5: ذكور | M5: إناث | N5: الإجمالي | O5: شعب | P5: ذكور | Q5: إناث | R5: الإجمالي | S5: شعب | T5: ذكور | U5: إناث | V5: الإجمالي | W5: شعب | X5: ذكور | Y5: إناث | Z5: الإجمالي | AA5: شعب | AB5: ذكور | AC5: إناث | AD5: الإجمالي | AE5: شعب | AF5: ذكور | AG5: إناث | AH5: الإجمالي | AI5: شعب | AJ5: ذكور | AK5: إناث | AL5: الإجمالي | AM5: شعب | AN5: ذكور | AO5: إناث | AP5: الإجمالي
A6: 1 | F6: =SUM(D6:E6) -> 0 | J6: =SUM(H6:I6) -> 0 | N6: =SUM(L6:M6) -> 0 | R6: =SUM(P6:Q6) -> 0 | V6: =SUM(T6:U6) -> 0 | Z6: =SUM(X6:Y6) -> 0 | AD6: =SUM(AB6:AC6) -> 0 | AH6: =SUM(AF6:AG6) -> 0 | AL6: =SUM(AJ6:AK6) -> 0 | AM6: =SUM(AI6,AE6,AA6,W6,S6,O6,K6,G6,C6) -> 0 | AN6: =SUM(AF6,AJ6,AB6,X6,T6,P6,L6,H6,D6) -> 0 | AO6: =SUM(AK6,AG6,AC6,Y6,U6,Q6,M6,I6,E6) -> 0 | AP6: =SUM(AN6:AO6) -> 0
A7: 2 | F7: =SUM(D7:E7) -> 0 | J7: =SUM(H7:I7) -> 0 | N7: =SUM(L7:M7) -> 0 | R7: =SUM(P7:Q7) -> 0 | V7: =SUM(T7:U7) -> 0 | Z7: =SUM(X7:Y7) -> 0 | AD7: =SUM(AB7:AC7) -> 0 | AH7: =SUM(AF7:AG7) -> 0 | AL7: =SUM(AJ7:AK7) -> 0 | AM7: =SUM(AI7,AE7,AA7,W7,S7,O7,K7,G7,C7) -> 0 | AN7: =SUM(AF7,AJ7,AB7,X7,T7,P7,L7,H7,D7) -> 0 | AO7: =SUM(AK7,AG7,AC7,Y7,U7,Q7,M7,I7,E7) -> 0 | AP7: =SUM(AN7:AO7) -> 0
A8: 3 | F8: =SUM(D8:E8) -> 0 | J8: =SUM(H8:I8) -> 0 | N8: =SUM(L8:M8) -> 0 | R8: =SUM(P8:Q8) -> 0 | V8: =SUM(T8:U8) -> 0 | Z8: =SUM(X8:Y8) -> 0 | AD8: =SUM(AB8:AC8) -> 0 | AH8: =SUM(AF8:AG8) -> 0 | AL8: =SUM(AJ8:AK8) -> 0 | AM8: =SUM(AI8,AE8,AA8,W8,S8,O8,K8,G8,C8) -> 0 | AN8: =SUM(AF8,AJ8,AB8,X8,T8,P8,L8,H8,D8) -> 0 | AO8: =SUM(AK8,AG8,AC8,Y8,U8,Q8,M8,I8,E8) -> 0 | AP8: =SUM(AN8:AO8) -> 0
A9: 4 | F9: =SUM(D9:E9) -> 0 | J9: =SUM(H9:I9) -> 0 | N9: =SUM(L9:M9) -> 0 | R9: =SUM(P9:Q9) -> 0 | V9: =SUM(T9:U9) -> 0 | Z9: =SUM(X9:Y9) -> 0 | AD9: =SUM(AB9:AC9) -> 0 | AH9: =SUM(AF9:AG9) -> 0 | AL9: =SUM(AJ9:AK9) -> 0 | AM9: =SUM(AI9,AE9,AA9,W9,S9,O9,K9,G9,C9) -> 0 | AN9: =SUM(AF9,AJ9,AB9,X9,T9,P9,L9,H9,D9) -> 0 | AO9: =SUM(AK9,AG9,AC9,Y9,U9,Q9,M9,I9,E9) -> 0 | AP9: =SUM(AN9:AO9) -> 0
A10: 5 | F10: =SUM(D10:E10) -> 0 | J10: =SUM(H10:I10) -> 0 | N10: =SUM(L10:M10) -> 0 | R10: =SUM(P10:Q10) -> 0 | V10: =SUM(T10:U10) -> 0 | Z10: =SUM(X10:Y10) -> 0 | AD10: =SUM(AB10:AC10) -> 0 | AH10: =SUM(AF10:AG10) -> 0 | AL10: =SUM(AJ10:AK10) -> 0 | AM10: =SUM(AI10,AE10,AA10,W10,S10,O10,K10,G10,C10) -> 0 | AN10: =SUM(AF10,AJ10,AB10,X10,T10,P10,L10,H10,D10) -> 0 | AO10: =SUM(AK10,AG10,AC10,Y10,U10,Q10,M10,I10,E10) -> 0 | AP10: =SUM(AN10:AO10) -> 0
A11: 6 | F11: =SUM(D11:E11) -> 0 | J11: =SUM(H11:I11) -> 0 | N11: =SUM(L11:M11) -> 0 | R11: =SUM(P11:Q11) -> 0 | V11: =SUM(T11:U11) -> 0 | Z11: =SUM(X11:Y11) -> 0 | AD11: =SUM(AB11:AC11) -> 0 | AH11: =SUM(AF11:AG11) -> 0 | AL11: =SUM(AJ11:AK11) -> 0 | AM11: =SUM(AI11,AE11,AA11,W11,S11,O11,K11,G11,C11) -> 0 | AN11: =SUM(AF11,AJ11,AB11,X11,T11,P11,L11,H11,D11) -> 0 | AO11: =SUM(AK11,AG11,AC11,Y11,U11,Q11,M11,I11,E11) -> 0 | AP11: =SUM(AN11:AO11) -> 0
A12: 7 | F12: =SUM(D12:E12) -> 0 | J12: =SUM(H12:I12) -> 0 | N12: =SUM(L12:M12) -> 0 | R12: =SUM(P12:Q12) -> 0 | V12: =SUM(T12:U12) -> 0 | Z12: =SUM(X12:Y12) -> 0 | AD12: =SUM(AB12:AC12) -> 0 | AH12: =SUM(AF12:AG12) -> 0 | AL12: =SUM(AJ12:AK12) -> 0 | AM12: =SUM(AI12,AE12,AA12,W12,S12,O12,K12,G12,C12) -> 0 | AN12: =SUM(AF12,AJ12,AB12,X12,T12,P12,L12,H12,D12) -> 0 | AO12: =SUM(AK12,AG12,AC12,Y12,U12,Q12,M12,I12,E12) -> 0 | AP12: =SUM(AN12:AO12) -> 0
A13: 8 | F13: =SUM(D13:E13) -> 0 | J13: =SUM(H13:I13) -> 0 | N13: =SUM(L13:M13) -> 0 | R13: =SUM(P13:Q13) -> 0 | V13: =SUM(T13:U13) -> 0 | Z13: =SUM(X13:Y13) -> 0 | AD13: =SUM(AB13:AC13) -> 0 | AH13: =SUM(AF13:AG13) -> 0 | AL13: =SUM(AJ13:AK13) -> 0 | AM13: =SUM(AI13,AE13,AA13,W13,S13,O13,K13,G13,C13) -> 0 | AN13: =SUM(AF13,AJ13,AB13,X13,T13,P13,L13,H13,D13) -> 0 | AO13: =SUM(AK13,AG13,AC13,Y13,U13,Q13,M13,I13,E13) -> 0 | AP13: =SUM(AN13:AO13) -> 0
A14: 9 | F14: =SUM(D14:E14) -> 0 | J14: =SUM(H14:I14) -> 0 | N14: =SUM(L14:M14) -> 0 | R14: =SUM(P14:Q14) -> 0 | V14: =SUM(T14:U14) -> 0 | Z14: =SUM(X14:Y14) -> 0 | AD14: =SUM(AB14:AC14) -> 0 | AH14: =SUM(AF14:AG14) -> 0 | AL14: =SUM(AJ14:AK14) -> 0 | AM14: =SUM(AI14,AE14,AA14,W14,S14,O14,K14,G14,C14) -> 0 | AN14: =SUM(AF14,AJ14,AB14,X14,T14,P14,L14,H14,D14) -> 0 | AO14: =SUM(AK14,AG14,AC14,Y14,U14,Q14,M14,I14,E14) -> 0 | AP14: =SUM(AN14:AO14) -> 0
A15: 10 | F15: =SUM(D15:E15) -> 0 | J15: =SUM(H15:I15) -> 0 | N15: =SUM(L15:M15) -> 0 | R15: =SUM(P15:Q15) -> 0 | V15: =SUM(T15:U15) -> 0 | Z15: =SUM(X15:Y15) -> 0 | AD15: =SUM(AB15:AC15) -> 0 | AH15: =SUM(AF15:AG15) -> 0 | AL15: =SUM(AJ15:AK15) -> 0 | AM15: =SUM(AI15,AE15,AA15,W15,S15,O15,K15,G15,C15) -> 0 | AN15: =SUM(AF15,AJ15,AB15,X15,T15,P15,L15,H15,D15) -> 0 | AO15: =SUM(AK15,AG15,AC15,Y15,U15,Q15,M15,I15,E15) -> 0 | AP15: =SUM(AN15:AO15) -> 0
A16: 11 | F16: =SUM(D16:E16) -> 0 | J16: =SUM(H16:I16) -> 0 | N16: =SUM(L16:M16) -> 0 | R16: =SUM(P16:Q16) -> 0 | V16: =SUM(T16:U16) -> 0 | Z16: =SUM(X16:Y16) -> 0 | AD16: =SUM(AB16:AC16) -> 0 | AH16: =SUM(AF16:AG16) -> 0 | AL16: =SUM(AJ16:AK16) -> 0 | AM16: =SUM(AI16,AE16,AA16,W16,S16,O16,K16,G16,C16) -> 0 | AN16: =SUM(AF16,AJ16,AB16,X16,T16,P16,L16,H16,D16) -> 0 | AO16: =SUM(AK16,AG16,AC16,Y16,U16,Q16,M16,I16,E16) -> 0 | AP16: =SUM(AN16:AO16) -> 0
A17: 12 | F17: =SUM(D17:E17) -> 0 | J17: =SUM(H17:I17) -> 0 | N17: =SUM(L17:M17) -> 0 | R17: =SUM(P17:Q17) -> 0 | V17: =SUM(T17:U17) -> 0 | Z17: =SUM(X17:Y17) -> 0 | AD17: =SUM(AB17:AC17) -> 0 | AH17: =SUM(AF17:AG17) -> 0 | AL17: =SUM(AJ17:AK17) -> 0 | AM17: =SUM(AI17,AE17,AA17,W17,S17,O17,K17,G17,C17) -> 0 | AN17: =SUM(AF17,AJ17,AB17,X17,T17,P17,L17,H17,D17) -> 0 | AO17: =SUM(AK17,AG17,AC17,Y17,U17,Q17,M17,I17,E17) -> 0 | AP17: =SUM(AN17:AO17) -> 0
... A25: 20 | F25: =SUM(D25:E25) -> 0 | J25: =SUM(H25:I25) -> 0 | N25: =SUM(L25:M25) -> 0 | R25: =SUM(P25:Q25) -> 0 | V25: =SUM(T25:U25) -> 0 | Z25: =SUM(X25:Y25) -> 0 | AD25: =SUM(AB25:AC25) -> 0 | AH25: =SUM(AF25:AG25) -> 0 | AL25: =SUM(AJ25:AK25) -> 0 | AM25: =SUM(AI25,AE25,AA25,W25,S25,O25,K25,G25,C25) -> 0 | AN25: =SUM(AF25,AJ25,AB25,X25,T25,P25,L25,H25,D25) -> 0 | AO25: =SUM(AK25,AG25,AC25,Y25,U25,Q25,M25,I25,E25) -> 0 | AP25: =SUM(AN25:AO25) -> 0
A26: الإجمالي | C26: =SUM(C6:C25) -> 0 | D26: =SUM(D6:D25) -> 0 | E26: =SUM(E6:E25) -> 0 | F26: =SUM(F6:F25) -> 0 | G26: =SUM(G6:G25) -> 0 | H26: =SUM(H6:H25) -> 0 | I26: =SUM(I6:I25) -> 0 | J26: =SUM(J6:J25) -> 0 | ... AP26: =SUM(AP6:AP25) -> 0
C28: رئيس قسم التخطيط والاحصاء | R28: مدير ادارة التربية والتعليم بالمديرية | AA28: رئيس قسم التخطيط والاحصاء | AI28: مدير ادارة التربية والتعليم بالمديرية

Sheet طلاب تحفيظ تكميلي
A10: م | B10: اسم المدرسة | C10: اول تكميلي | G10: ثاني تكميلي | K10: ثالث تكميلي | O10: الإجمالي
C11: شعب | D11: ذكور | E11: إناث | F11: إجمالي | G11: شعب | H11: ذكور | I11: إناث | J11: إجمالي | K11: شعب | L11: ذكور | M11: إناث | N11: إجمالي | O11: شعب | P11: ذكور | Q11: إناث | R11: إجمالي
A12: 1 | F12: =SUM(D12:E12) -> 0 | J12: =SUM(H12:I12) -> 0 | N12: =SUM(L12:M12) -> 0 | O12: =C12+G12+K12 -> 0 | P12: =D12+H12+L12 -> 0 | Q12: =E12+I12+M12 -> 0 | R12: =SUM(P12:Q12) -> 0
A13: 2 | F13: =SUM(D13:E13) -> 0 | J13: =SUM(H13:I13) -> 0 | N13: =SUM(L13:M13) -> 0 | O13: =C13+G13+K13 -> 0 | P13: =D13+H13+L13 -> 0 | Q13: =E13+I13+M13 -> 0 | R13: =SUM(P13:Q13) -> 0
A14: 3 | F14: =SUM(D14:E14) -> 0 | J14: =SUM(H14:I14) -> 0 | N14: =SUM(L14:M14) -> 0 | O14: =C14+G14+K14 -> 0 | P14: =D14+H14+L14 -> 0 | Q14: =E14+I14+M14 -> 0 | R14: =SUM(P14:Q14) -> 0
A15: 4 | F15: =SUM(D15:E15) -> 0 | J15: =SUM(H15:I15) -> 0 | N15: =SUM(L15:M15) -> 0 | O15: =C15+G15+K15 -> 0 | P15: =D15+H15+L15 -> 0 | Q15: =E15+I15+M15 -> 0 | R15: =SUM(P15:Q15) -> 0
A16: 5 | F16: =SUM(D16:E16) -> 0 | J16: =SUM(H16:I16) -> 0 | N16: 0 | O16: =C16+G16+K16 -> 0 | P16: =D16+H16+L16 -> 0 | Q16: =E16+I16+M16 -> 0 | R16: =SUM(P16:Q16) -> 0
A17: 6 | F17: =SUM(D17:E17) -> 0 | J17: =SUM(H17:I17) -> 0 | N17: =SUM(L17:M17) -> 0 | O17: =C17+G17+K17 -> 0 | P17: =D17+H17+L17 -> 0 | Q17: =E17+I17+M17 -> 0 | R17: =SUM(P17:Q17) -> 0
A18: 7 | F18: =SUM(D18:E18) -> 0 | J18: =SUM(H18:I18) -> 0 | N18: 0 | O18: =C18+G18+K18 -> 0 | P18: =D18+H18+L18 -> 0 | Q18: =E18+I18+M18 -> 0 | R18: =SUM(P18:Q18) -> 0
A19: 8 | F19: =SUM(D19:E19) -> 0 | J19: =SUM(H19:I19) -> 0 | N19: 0 | O19: =C19+G19+K19 -> 0 | P19: =D19+H19+L19 -> 0 | Q19: =E19+I19+M19 -> 0 | R19: =SUM(P19:Q19) -> 0
A20: 9 | F20: =SUM(D20:E20) -> 0 | J20: =SUM(H20:I20) -> 0 | N20: 0 | O20: =C20+G20+K20 -> 0 | P20: =D20+H20+L20 -> 0 | Q20: =E20+I20+M20 -> 0 | R20: =SUM(P20:Q20) -> 0
A21: 10 | F21: =SUM(D21:E21) -> 0 | J21: =SUM(H21:I21) -> 0 | N21: 0 | O21: =C21+G21+K21 -> 0 | P21: =D21+H21+L21 -> 0 | Q21: =E21+I21+M21 -> 0 | R21: =SUM(P21:Q21) -> 0
A22: 11 | F22: =SUM(D22:E22) -> 0 | J22: =SUM(H22:I22) -> 0 | N22: 0 | O22: =C22+G22+K22 -> 0 | P22: =D22+H22+L22 -> 0 | Q22: =E22+I22+M22 -> 0 | R22: =SUM(P22:Q22) -> 0
A23: 12 | F23: =SUM(D23:E23) -> 0 | J23: =SUM(H23:I23) -> 0 | N23: 0 | O23: =C23+G23+K23 -> 0 | P23: =D23+H23+L23 -> 0 | Q23: =E23+I23+M23 -> 0 | R23: =SUM(P23:Q23) -> 0
A24: 13 | F24: =SUM(D24:E24) -> 0 | J24: =SUM(H24:I24) -> 0 | N24: 0 | O24: =C24+G24+K24 -> 0 | P24: =D24+H24+L24 -> 0 | Q24: =E24+I24+M24 -> 0 | R24: =SUM(P24:Q24) -> 0
A25: 14 | F25: =SUM(D25:E25) -> 0 | J25: =SUM(H25:I25) -> 0 | N25: 0 | O25: =C25+G25+K25 -> 0 | P25: =D25+H25+L25 -> 0 | Q25: =E25+I25+M25 -> 0 | R25: =SUM(P25:Q25) -> 0
A26: 15 | F26: =SUM(D26:E26) -> 0 | J26: =SUM(H26:I26) -> 0 | N26: 0 | O26: =C26+G26+K26 -> 0 | P26: =D26+H26+L26 -> 0 | Q26: =E26+I26+M26 -> 0 | R26: =SUM(P26:Q26) -> 0
A27: 16 | F27: =SUM(D27:E27) -> 0 | J27: =SUM(H27:I27) -> 0 | N27: 0 | O27: =C27+G27+K27 -> 0 | P27: =D27+H27+L27 -> 0 | Q27: =E27+I27+M27 -> 0 | R27: =SUM(P27:Q27) -> 0
A28: 17 | F28: =SUM(D28:E28) -> 0 | J28: =SUM(H28:I28) -> 0 | N28: 0 | O28: =C28+G28+K28 -> 0 | P28: =D28+H28+L28 -> 0 | Q28: =E28+I28+M28 -> 0 | R28: =SUM(P28:Q28) -> 0
A29: 18 | F29: =SUM(D29:E29) -> 0 | J29: =SUM(H29:I29) -> 0 | N29: 0 | O29: =C29+G29+K29 -> 0 | P29: =D29+H29+L29 -> 0 | Q29: =E29+I29+M29 -> 0 | R29: =SUM(P29:Q29) -> 0
... A31: 20 | F31: =SUM(D31:E31) -> 0 | J31: =SUM(H31:I31) -> 0 | N31: 0 | O31: =C31+G31+K31 -> 0 | P31: =D31+H31+L31 -> 0 | Q31: =E31+I31+M31 -> 0 | R31: =SUM(P31:Q31) -> 0
A32: الاجمالي | C32: =SUM(C12:C31) -> 0 | D32: =SUM(D12:D31) -> 0 | E32: =SUM(E12:E31) -> 0 | F32: =SUM(F12:F31) -> 0 | G32: =SUM(G12:G31) -> 0 | H32: =SUM(H12:H31) -> 0 | I32: =SUM(I12:I31) -> 0 | J32: =SUM(J12:J31) -> 0 | ... N32: =SUM(N12:N31) -> 0 | O32: =C32+G32+K32 -> 0 | P32: =D32+H32+L32 -> 0 | Q32: =E32+I32+M32 -> 0 | R32: =SUM(P32:Q32) -> 0
C34: قسم الاحصاء والتخطيط

Sheet قوى عاملة تحفيظ أولي وتكميلي
A4: م | B4: اسم المدرسة | C4: مدير | E4: وكيل | G4: مدرس | I4: اخرى | K4: الإجمالي
C5: ذ | D5: ث | E5: ذ | F5: ث | G5: ذ | H5: ث | I5: ذ | J5: ث | K5: ذ | L5: ث | M5: ج
A6: 1
A7: 2
A8: 3
A9: 4
A10: 5
A11: 6
A12: 7
A13: 8
A14: 9
A15: 10
A16: 11
A17: 12
... A25: 20
A26: الاجمالي | C26: =SUM(C6:C25) -> 0 | D26: =SUM(D6:D25) -> 0 | E26: =SUM(E6:E25) -> 0 | F26: =SUM(F6:F25) -> 0 | G26: =SUM(G6:G25) -> 0 | H26: =SUM(H6:H25) -> 0 | I26: =SUM(I6:I25) -> 0 | J26: =SUM(J6:J25) -> 0 | ... M26: =SUM(M6:M25) -> 0
A28: رئيس قسم التخطيط والإحصاء | K28: مدير إدارة التربية في المديرية

Sheet احصائيات بمكونات المبنى تجميع م
A8: م | B8: اسم المدرسة | C8: مبنى مدرسي | D8: عمارة | E8: أخرى تذكر | F8: عدد غرف المدرسة | I8: صلاحية الغرف الدراسية | L8: إدارة المدرسة | N8: قاعة | P8: استراحة مدرسين | R8: مكتبة | T8: مسرح / محتوياته | V8: عدد الحمامات | X8: سور المدرسة | Z8: كهرباء حكومي/ أهلي | AB8: المياه/ حكومي/ أهلي | AD8: غرفة مقصف | AF8: غرف معامل | AH8: طريق سيارة
N9: اجتماعات
F10: اساسي | G10: ثانوي | H10: إجمالي | I10: صالح | J10: يحتاج ترميم | K10: غير صالح | L10: يوجد | M10: لا يوجد | N10: يوجد | O10: لا يوجد | P10: يوجد | Q10: لا يوجد | R10: يوجد | S10: لا يوجد | T10: يوجد | U10: لا يوجد | V10: يوجد | W10: لا يوجد | X10: يوجد | Y10: لا يوجد | Z10: يوجد | AA10: لا يوجد | AB10: يوجد | AC10: لا يوجد | AD10: يوجد | AE10: لا يوجد | AF10: يوجد | AG10: لا يوجد | AH10: يوجد | AI10: لا يوجد
A11: 1
A12: 2
A13: 3
A14: 4
A15: 5
A16: 6
A17: 7
A18: 8
A19: 9
A20: 10
A21: 11
A22: 12
... A30: 20
B32: رئيس قسم التخطيط والاحصاء | U32: مدير ادارة التربية والتعليم بالمديرية

Sheet   مكونات المبنى المدرسة 
A7: إحصائيات توضح مكونات المبنى المدرسي في المدارس العاملة وبحسب المرحلة الدراسية حكومي
A8: مدرسة:.............................مديرية.......................للعام الدراسي 2025 - 2026 م
A9: مكونات المبنى المدرسي
A10: مبنى مدرسي | B10: عمارة | C10: أخرى تذكر | D10: عدد الغرف المدرسية في المبنى كاملة | G10: صلاحية الغرف الدراسية | J10: الغرف الدراسيسة فقط | K10: إدارة المدرسة | M10: استراحة مدرسين | O10: مسرح/ محتوياته | Q10: عدد الحمامات | S10: سور المدرسة يحيط بها | U10: كهرباء حكومي/ أهلي | W10: المياه | Y10: مقصف | AA10: طريق سيارة | AC10: اسم المدرسة
D11: أساسي | E11: ثانوي | F11: إجمالي | G11: صالح | H11: يحتاج ترميم | I11: غير صالح | K11: يوجد | L11: لا يوجد | M11: يوجد | N11: لا يوجد | O11: يوجد | P11: لا يوجد | Q11: صالحة | R11: غير صالحة | S11: يوجد | T11: لا يوجد | U11: شاشة تلفزيون | V11: منظومة طاقة | W11: يوجد | X11: لا يوجد | Y11: يوجد | Z11: لا يوجد | AA11: يوجد | AB11: لا يوجد
B17: مدير المدرسة | L17: رئيس قسم التخطيط والاحصاء | V17: مدير ادارة التربية والتعليم بالمديرية

Sheet التجهيزات المدرسة
A7: إحصائيات توضح توزيع التجهيزات في المدارس العاملة وبحسب المرحلة الدراسية والجهة الإشرافية
A8: مدرسة: .........................مديرية.......................للعام الدراسي 2025 - 2026 م
A9: توزيع الأثاث والتجهيزات
A10: معمل أساسي | B10: معمل ثانوي ونوعه | C10: معمل رياضيات | D10: معمل حاسوب | E10: معمل خياطة | F10: إذاعة | G10: طابعة | H10: مكتب للإدارة | I10: كنب | J10: مقاعد مندوجة | K10: مقاعد فردية | L10: طاولات فردية | M10: طاولات اجتماعات | N10: مكيف | O10: مراوح | P10: دواليب | Q10: مكاتب سكرتارية | R10: ثلاجة | S10: تلفون ثابت | T10: جهاز عرض | U10: شاشة تلفزيون | V10: منظومة طاقة | W10: مولد كهرباء | X10: كاميرة رقمية | Y10: آلة تصوير | Z10: شبكة نت | AA10: قاعة تدريب | AB10: غرفة أنشطة | AC10: غرفة تدبير منزلي | AD10: سبورات بيضاء | AE10: سبورات سوداء | AF10: سبورات الكترونية | AG10: ملعب طائرة | AH10: ملعب قدم | AI10: أخرى تذكر
B16: مدير المدرسة | N16: رئيس قسم التخطيط والاحصاء | V16: مدير ادارة التربية والتعليم بالمديرية

Sheet المديرية بالتجهيزات المدرسية
A8: م | B8: اسم المدرسة | C8: معمل اساسي | D8: معمل ثانوي/ نوعه | E8: معمل رياضيات | F8: معمل حاسوب | G8: معمل خياطة | H8: إذاعة مدرسية | I8: طابعة كمبيوتر | J8: مكتب للإدارة | K8: كنب للإدارة | L8: مقاعد مزدوجة | M8: مقاعد فردية | N8: طاولات فردية | O8: طاولة اجتماعات | P8: مكيف | Q8: مراوح | R8: دواليب | S8: مكاتب سكرتارية | T8: ثلاجة | U8: تلفون ثابت | V8: جهاز عرض | W8: شاشة عرض | X8: منظومة طاقة شمسية | Y8: مولد كهرباء | Z8: كاميرة تصوير رقمية | AA8: مسرح | AB8: آلة تصوير ورق | AC8: شبكة نت | AD8: قاعة تدريب | AE8: غرفة أنشطة | AF8: غرفة تدبير منزلي | AG8: سبورات بيضاء | AH8: سبورات سوداء | AI8: سبورات الكترونية | AJ8: ملعب طائرة ملعب قدم | AK8: ملعب قدم | AL8: أخرى تذكر
A9: 1
A10: 2
A11: 3
A12: 4
A13: 5
A14: 6
A15: 7
A16: 8
A17: 9
A18: 10
A19: 11
A20: 12
... A28: 20
C30: رئيس قسم التخطيط والاحصاء | Q30: مدير ادارة التربية والتعليم بالمديرية

Sheet  خاص بالمدرسة النازحين تجميع م
A3: م | B3: الاســــم | C3: المؤهل | D3: التخصص | E3: المادة التي يدرسها | F3: الصف | G3: عدد الحصص | H3: المحافظة الوافد منها | I3: المديرية | J3: المدرسة | K3: رقم الهاتف
A4: 1
A5: 2
A6: 3
A7: 4
A8: 5
A9: 6
A10: 7
A11: 8
A12: 9
A13: 10
A14: 11
A15: 12
... A23: 20

Sheet  خاص بالمدرسة النازحين
A3: م | B3: الاســــم | C3: المؤهل | D3: التخصص | E3: المادة التي يدرسها | F3: الصف | G3: عدد الحصص | H3: المحافظة الوافد منها | I3: المديرية | J3: المدرسة | K3: رقم الهاتف
A4: 1
A5: 2
A6: 3
A7: 4
A8: 5
A9: 6
A10: 7
A11: 8
A12: 9
A13: 10
A14: 11
A15: 12
... A23: 20

Sheet النازحين خارج المدرسة
A3: م | B3: الاســــم | C3: المؤهل | D3: التخصص | E3: المادة التي يدرسها | F3: الصف | G3: عدد الحصص | H3: مكان النزوح الحالي | I3: المديرية | J3: المدرسة | K3: يعمل / لايعمل | L3: رقم الهاتف
A4: 1
A5: 2
A6: 3
A7: 4
A8: 5
A9: 6
A10: 7
A11: 8
A12: 9
A13: 10
A14: 11
A15: 12
... A23: 20

Sheet المتطوعين في المدرسة
A3: م | B3: الاســــم | C3: المؤهل | D3: التخصص | E3: المادة التي يدرسها | F3: الصف | G3: عدد الحصص | H3: رقم البطاقة | I3: سنوات التطوع | J3: رقم الهاتف | K3: ملاحظات
A4: 1
A5: 2
A6: 3
A7: 4
A8: 5
A9: 6
A10: 7
A11: 8
A12: 9
A13: 10
A14: 11
A15: 12
... A23: 20

Sheet  المتطوعين تجميع المديرية
A3: م | B3: الاســــم | C3: المؤهل | D3: التخصص | E3: المادة التي يدرسها | F3: الصف | G3: عدد الحصص | H3: رقم البطاقة | I3: سنوات التطوع | J3: رقم الهاتف | K3: ملاحظات
A4: 1
A5: 2
A6: 3
A7: 4
A8: 5
A9: 6
A10: 7
A11: 8
A12: 9
A13: 10
A14: 11
A15: 12
... A23: 20
