Workbook
Name Q_SEND_PAYROALL: بيانات!$B$1:$G$1
Name Q_SEND_PAYROALL: #REF!

Sheet ورقة1
G1: الادارة المحلية | K1: التعزية
G2: الاشغال العامة والطرق | K2: الشمايتين
G3: الاعلام | K3: الصلو
G4: الاوقاف قطاع التوجيه والارشاد | K4: القاهرة
G5: التخطيط والتعاون الدولي | K5: المخاء
G6: التربية والتعليم | K6: المسراخ
G7: التعليم الفني والتدريب المهني | K7: المظفر
G8: الثقافة | K8: المعافر
G9: الخدمة المدنية والتأمينات | K9: المواسط
G10: الزراعة والري | K10: الوازعية
G11: السياحة | K11: جبل حبشي
G12: الشباب والرياضة | K12: حيفان
... G19: شئون المغتربين | K19: صبر الموادم
K20: ماوية
K21: مركز المحافظة
K22: مشرعة وحدنان
K23: مقبنة
K24: موزع
A91: 1 | B91: واحد
A92: 2 | B92: اثنان
A93: 3 | B93: ثلاثة
A94: 4 | B94: أربعة
A95: 5 | B95: خمسة
A96: 6 | B96: ستة
A97: 7 | B97: سبعة
A98: 8 | B98: ثمانية
A99: 9 | B99: تسعة
A100: 10 | B100: عشرة
A101: 11 | B101: أحد عشر
A102: 12 | B102: أثنى عشر
... A120: 30 | B120: ثلاثون

Sheet بيانات
A1: الرقم المالي | B1: الوحدة الادارية | D1: الرقم الوظيفي | E1: اسم الموظف | F1: المديرية | G1: الدرجةالوظيفية | H1: شهر البيانات | I1: الراتب الاساسي | J1: تاريخ الميلاد | K1: تاريخ التعيين | L1: حالة الموظف | M1: الفرع
A2: 433091 | B2: التربية والتعليم | D2: 2206176 | E2: ابتسام سعيد سلام احمد | F2: الشمايتين | G2: الثالثة عشرة | H2: 45474 | I2: 49427 | J2: 28856 | K2: 40909 | M2: -7يوليوعزاعز/الشمايتين
A3: 267401 | B3: التربية والتعليم | D3: 1168586 | E3: ابتسام سلطان سعيد اسماعيل | F3: الشمايتين | G3: السابعة | H3: 45474 | I3: 85697 | J3: 28491 | K3: 35407 | M3: الوحده شرق بني شيبه بنات
A4: 368971 | B4: التربية والتعليم | D4: 1192690 | E4: ابتسام عبدالحكيم محمد الحبشي | F4: الشمايتين | G4: الثامنة | H4: 45474 | I4: 82478 | J4: 28126 | K4: 35779 | M4: الوحده بالتربه
A5: 267407 | B5: التربية والتعليم | D5: 1167904 | E5: ابتسام عبدالله سيف سعيد | F5: الشمايتين | G5: السابعة | H5: 45474 | I5: 85697 | J5: 26665 | K5: 35490 | M5: المعافر ( ا, ع. ث )
A6: 70301266 | B6: التربية والتعليم | D6: 1196990 | E6: ابتسام عبدالله قاسم علي | F6: الشمايتين | G6: السابعة | H6: 45474 | I6: 85697 | J6: 27030 | K6: 35037 | M6: النهضة للبنات
A7: 433109 | B7: التربية والتعليم | D7: 2206194 | E7: ابتسام عبده محمد فارع المذحجي | F7: الشمايتين | G7: الثالثة عشرة | H7: 45474 | I7: 49427 | J7: 27760 | K7: 40909 | M7: -7يوليوعزاعز/الشمايتين
A8: 103730 | B8: التربية والتعليم | D8: 1181718 | E8: ابتسام عبده مقبل علي | F8: الشمايتين | G8: الخامسة | H8: 45474 | I8: 98635 | J8: 25204 | K8: 33615 | M8: النهضة للبنات
A9: 272374 | B9: التربية والتعليم | D9: 1595517 | E9: ابتسام محمد امين قاسم الشرجبي | F9: الشمايتين | G9: السابعة | H9: 45474 | I9: 85697 | J9: 27760 | K9: 37991 | M9: مدرسة 13 يونيو - شرجب
A10: 15696 | B10: التربية والتعليم | D10: 1172366 | E10: ابتسام محمد سلام سعيد الشرجبي | F10: الشمايتين | G10: الرابعة | H10: 45474 | I10: 103631 | J10: 25569 | K10: 32786 | L10: تقاعد بالخدمة | M10: مدرسة 13 يونيو - شرجب
A11: 270620 | B11: التربية والتعليم | D11: 1472043 | E11: ابتهال احمد شمسان سلام | F11: الشمايتين | G11: السادسة | H11: 45474 | I11: 94214 | J11: 27760 | K11: 36869 | M11: المرحوم/ سلام سعيد
A12: 273970 | B12: التربية والتعليم | D12: 2133825 | E12: ابتهال ياسين محمد احمد الاديمي | F12: الشمايتين | G12: التاسعة | H12: 45474 | I12: 70422 | J12: 28126 | K12: 40138 | M12: المساجد اديم/
A13: 170902 | B13: التربية والتعليم | D13: 1535832 | E13: ابراهيم احمد عبدالرقيب الهتاري | F13: الشمايتين | G13: السادسة | H13: 45474 | I13: 94214 | J13: 28126 | K13: 37230 | M13: عثمان بن عفان للبنات
A14: 113937 | B14: التربية والتعليم | D14: 1185572 | E14: ابراهيم احمد عبده علي | F14: الشمايتين | G14: الثالثة | H14: 45474 | I14: 115277 | J14: 24473 | K14: 34263 | M14: حفصه للبنات
A15: 38557 | B15: التربية والتعليم | D15: 1181353 | E15: ابراهيم حميد محمد مجاهد الاكحلي | F15: الشمايتين | G15: الخامسة | H15: 45474 | I15: 98635 | J15: 26299 | K15: 33863 | M15: الفقيد النعمان
A16: 262570 | B16: التربية والتعليم | D16: 1183363 | E16: ابراهيم درهم عبدالرحمن محمود | F16: الشمايتين | G16: السادسة | H16: 45474 | I16: 89525 | J16: 27395 | K16: 35021 | M16: عمر بن الخطاب / دبع الداخل
A17: 131524 | B17: التربية والتعليم | D17: 1171557 | E17: ابراهيم سفيان احمد سليمان | F17: الشمايتين | G17: السادسة | H17: 45474 | I17: 94214 | J17: 26665 | K17: 34660 | M17: الشهيد عبدالرحمن الغافقي
A18: 113587 | B18: التربية والتعليم | D18: 1172081 | E18: ابراهيم سيف هاشم عون | F18: الشمايتين | G18: السادسة | H18: 45474 | I18: 94214 | J18: 27030 | K18: 34358 | M18: مدرسة اسامه بن زيد
A19: 130924 | B19: التربية والتعليم | D19: 1169293 | E19: ابراهيم طاهر غالب عبدالله | F19: الشمايتين | G19: السادسة | H19: 45474 | I19: 94214 | J19: 27395 | K19: 34646 | M19: الميهال جبل صبران
A20: 117208 | B20: التربية والتعليم | D20: 1180407 | E20: ابراهيم عبدالملك عبدالحميد الشيباني | F20: الشمايتين | G20: الثالثة | H20: 45474 | I20: 115277 | J20: 25204 | K20: 34266 | M20: -26سبتمبر(أ)بالسويقه/الشمايتين
A21: 117143 | B21: التربية والتعليم | D21: 1281709 | E21: ابراهيم عبده محمد المقري | F21: الشمايتين | G21: الرابعة | H21: 45474 | I21: 100743 | J21: 25569 | K21: 34259 | M21: ـ26سبتمبر زكيره/الشمايتين
A22: 380869 | B22: التربية والتعليم | D22: 1112231 | E22: ابراهيم فضل مقبل الحصيني | F22: الشمايتين | G22: الثامنة | H22: 45474 | I22: 80472 | J22: 27760 | K22: 35785 | M22: إدارة التربية والتعليم بالمديرية
A23: 907 | B23: التربية والتعليم | D23: 1172210 | E23: ابراهيم محمد عوض المعمري | F23: الشمايتين | G23: الثالثة | H23: 45474 | I23: 96536 | J23: 20821 | K23: 28415 | L23: بالغ أحد الأجلين | M23: الامل بني عمر/الشمايتين
A24: 260393 | B24: التربية والتعليم | D24: 1174016 | E24: ابوالاسرار احمد احمد ابوالاسرار | F24: الشمايتين | G24: الخامسة | H24: 45474 | I24: 95955 | J24: 22647 | K24: 35057 | L24: تقاعد بالعمر | M24: إدارة التربية والتعليم بالمديرية
A25: 270585 | B25: التربية والتعليم | D25: 1472045 | E25: ابوبكر سيف احمد صالح | F25: الشمايتين | G25: التاسعة | H25: 45474 | I25: 77868 | J25: 26299 | K25: 36865 | M25: الزكيره
A26: 13954 | B26: التربية والتعليم | D26: 1171653 | E26: ابوبكر سيف هاشم عون | F26: الشمايتين | G26: الثالثة | H26: 45474 | I26: 115277 | J26: 25204 | K26: 32559 | L26: تقاعد بالخدمة | M26: الفقيد النعمان
A27: 133016 | B27: التربية والتعليم | D27: 1176402 | E27: ابوبكر سيف هائل عبدالله الشيباني | F27: الشمايتين | G27: السادسة | H27: 45474 | I27: 95502 | J27: 25204 | K27: 34687 | M27: الاصلاح/غرب بني شيبه/الشمايتين
A28: 113664 | B28: التربية والتعليم | D28: 1175654 | E28: ابوبكر عبدالباري علي نعمان | F28: الشمايتين | G28: السادسة | H28: 45474 | I28: 94214 | J28: 27030 | K28: 34358 | M28: الشهيد/ احمد سيف الشرجبي
A29: 110788 | B29: التربية والتعليم | D29: 1174084 | E29: ابوبكر عبدالرقيب عبدالوهاب | F29: الشمايتين | G29: الخامسة | H29: 45474 | I29: 98635 | J29: 24838 | K29: 33864 | M29: الفجر الجديد بالتربة
A30: 130897 | B30: التربية والتعليم | D30: 1169948 | E30: ابوبكر عبدالله علي محمد الاصبحي | F30: الشمايتين | G30: السادسة | H30: 45474 | I30: 94214 | J30: 26665 | K30: 34646 | M30: إدارة التربية والتعليم بالمديرية
A31: 262227 | B31: التربية والتعليم | D31: 1179461 | E31: ابوبكر محمد عثمان فارع | F31: الشمايتين | G31: السادسة | H31: 45474 | I31: 95502 | J31: 25204 | K31: 35059 | M31: الميهال جبل صبران
A32: 38558 | B32: التربية والتعليم | D32: 1171989 | E32: ابوبكر محمد علوان الاصبحي | F32: الشمايتين | G32: الخامسة | H32: 45474 | I32: 98635 | J32: 25569 | K32: 33863 | M32: النجاح اصابح
A33: 38273 | B33: التربية والتعليم | D33: 1175982 | E33: ابوبكر مهيوب علي عبدان | F33: الشمايتين | G33: الخامسة | H33: 45474 | I33: 98635 | J33: 25204 | K33: 33875 | M33: الشهيد/ طه عبدالوارث
A34: 272207 | B34: التربية والتعليم | D34: 1595532 | E34: اتفاق احمد شمسان محمود ناصر المذحجي | F34: الشمايتين | G34: السابعة | H34: 45474 | I34: 85697 | J34: 28856 | K34: 37991 | M34: الجيل الجديد مداحج/الشمايتين
A35: 433172 | B35: التربية والتعليم | D35: 2206266 | E35: اتفاق سلطان احمد غالب | F35: الشمايتين | G35: العاشرة | H35: 45474 | I35: 61147 | J35: 28856 | K35: 40909 | M35: النهضة للبنات
A36: 417089 | B36: التربية والتعليم | D36: 2072969 | E36: اجلال فؤاد احمد علي | F36: الشمايتين | G36: الثامنة | H36: 45474 | I36: 81297 | J36: 29221 | K36: 38791 | M36: التعاون مشارقه/الشمايتين
A37: 369039 | B37: التربية والتعليم | D37: 1197017 | E37: احسان احمد سلام صالح | F37: الشمايتين | G37: السابعة | H37: 45474 | I37: 85697 | J37: 28126 | K37: 34762 | M37: م/ المثنى بن حارثه
A38: 272628 | B38: التربية والتعليم | D38: 1595535 | E38: احلام انور علي الرعدي | F38: الشمايتين | G38: الثامنة | H38: 45474 | I38: 81298 | J38: 28856 | K38: 38648 | M38: النهضة للبنات
... A49: 260374 | B49: التربية والتعليم | D49: 1172082 | E49: احمد بجاش محمد خظر | F49: الشمايتين | G49: السابعة | H49: 45474 | I49: 85697 | J49: 23743 | K49: 35150 | M49: السلام راسن
A50: 111226 | B50: التربية والتعليم | D50: 1184239 | E50: احمد ردمان علي عبده القرشي | F50: الشمايتين | G50: الخامسة | H50: 45474 | I50: 99975 | J50: 23012 | K50: 34155 | L50: تقاعد بالعمر | M50: خوله بنت الازور
...

Sheet التربية والتعليم_x0009__x0009__
G2: مديرية: | H2: =D5 -> الشمايتين
A3: مكتب الخدمة المدنية والتأمينات م/ تعز
A4: مركز تكنولوجيا المعلومات | F4: شهر: | H4: مارس | K4: =NOW() -> 46044.443
A5: فرع الخدمة المدنية بمديرية | D5: الشمايتين
D6: ؤ | E6: يرجى ضبط التاريخ في الجهاز الذي يقوم بإعداد هذه الكشوفات.
D8: ؤ | E8: لا ينظر إلى الاسم المرفوع به غياب من خارج المديرية حتى يتم إنهاء المناقلة.
D10: ؤ | E10: يراعى رفع الكشوفات في موعد أقصاه ( اليوم الثامن من الشهر ).
D12: ؤ | E12: يـرجـــــى عـــــدم الكـتـابـــــة بـخـــــط الـيـــــد بـعـــــد طـبـاعـــــة الكـشـــــف.
C14: كشف بغياب فرع مكتب | E14: التربية والتعليم
A17: م | B17: الرقم المالي | C17: الرقم الوظيفي | D17: الاســـــــــم | E17: الفــــــــــــرع | F17: المديرية | G17: العـمــر | H17: الخدمة | I17: عدد أيام الغياب | K17: الملاحظـــات
I18: رقمـاً | J18: بالأحـــرف
A19: {=IF(B19="","",ROW(1:1))} | C19: =IF(B19=0,"",VLOOKUP(B19,بيانات!A:H,4,FALSE)) | D19: =IF(B19=0,"",VLOOKUP(B19,بيانات!A:H,5,FALSE)) | E19: =IF(B19=0,"",VLOOKUP(B19,بيانات!A:M,13,FALSE)) | F19: =IF(B19=0,"",VLOOKUP(B19,بيانات!A:H,6,FALSE)) | J19: =IF(I19=0,"",VLOOKUP(I19,ورقة1!A:B,2,FALSE)) | K19: =IF(B19=0,"",IF(VLOOKUP(B19,بيانات!A:L,12,FALSE)=0,"",VLOOKUP(B19,بيانات!A:L,12,FALSE))) | L19: نموذج الغياب الموحد - 2 ( أغسطس 2024 )
A20: {=IF(B20="","",ROW(2:2))} | C20: =IF(B20=0,"",VLOOKUP(B20,بيانات!A:H,4,FALSE)) | D20: =IF(B20=0,"",VLOOKUP(B20,بيانات!A:H,5,FALSE)) | E20: =IF(B20=0,"",VLOOKUP(B20,بيانات!A:M,13,FALSE)) | F20: =IF(B20=0,"",VLOOKUP(B20,بيانات!A:H,6,FALSE)) | J20: =IF(I20=0,"",VLOOKUP(I20,ورقة1!A:B,2,FALSE)) | K20: =IF(B20=0,"",IF(VLOOKUP(B20,بيانات!A:L,12,FALSE)=0,"",VLOOKUP(B20,بيانات!A:L,12,FALSE)))
A21: {=IF(B21="","",ROW(3:3))} | C21: =IF(B21=0,"",VLOOKUP(B21,بيانات!A:H,4,FALSE)) | D21: =IF(B21=0,"",VLOOKUP(B21,بيانات!A:H,5,FALSE)) | E21: =IF(B21=0,"",VLOOKUP(B21,بيانات!A:M,13,FALSE)) | F21: =IF(B21=0,"",VLOOKUP(B21,بيانات!A:H,6,FALSE)) | J21: =IF(I21=0,"",VLOOKUP(I21,ورقة1!A:B,2,FALSE)) | K21: =IF(B21=0,"",IF(VLOOKUP(B21,بيانات!A:L,12,FALSE)=0,"",VLOOKUP(B21,بيانات!A:L,12,FALSE)))
A22: {=IF(B22="","",ROW(4:4))} | C22: =IF(B22=0,"",VLOOKUP(B22,بيانات!A:H,4,FALSE)) | D22: =IF(B22=0,"",VLOOKUP(B22,بيانات!A:H,5,FALSE)) | E22: =IF(B22=0,"",VLOOKUP(B22,بيانات!A:M,13,FALSE)) | F22: =IF(B22=0,"",VLOOKUP(B22,بيانات!A:H,6,FALSE)) | J22: =IF(I22=0,"",VLOOKUP(I22,ورقة1!A:B,2,FALSE)) | K22: =IF(B22=0,"",IF(VLOOKUP(B22,بيانات!A:L,12,FALSE)=0,"",VLOOKUP(B22,بيانات!A:L,12,FALSE)))
A23: {=IF(B23="","",ROW(5:5))} | C23: =IF(B23=0,"",VLOOKUP(B23,بيانات!A:H,4,FALSE)) | D23: =IF(B23=0,"",VLOOKUP(B23,بيانات!A:H,5,FALSE)) | E23: =IF(B23=0,"",VLOOKUP(B23,بيانات!A:M,13,FALSE)) | F23: =IF(B23=0,"",VLOOKUP(B23,بيانات!A:H,6,FALSE)) | J23: =IF(I23=0,"",VLOOKUP(I23,ورقة1!A:B,2,FALSE)) | K23: =IF(B23=0,"",IF(VLOOKUP(B23,بيانات!A:L,12,FALSE)=0,"",VLOOKUP(B23,بيانات!A:L,12,FALSE)))
A24: {=IF(B24="","",ROW(6:6))} | C24: =IF(B24=0,"",VLOOKUP(B24,بيانات!A:H,4,FALSE)) | D24: =IF(B24=0,"",VLOOKUP(B24,بيانات!A:H,5,FALSE)) | E24: =IF(B24=0,"",VLOOKUP(B24,بيانات!A:M,13,FALSE)) | F24: =IF(B24=0,"",VLOOKUP(B24,بيانات!A:H,6,FALSE)) | J24: =IF(I24=0,"",VLOOKUP(I24,ورقة1!A:B,2,FALSE)) | K24: =IF(B24=0,"",IF(VLOOKUP(B24,بيانات!A:L,12,FALSE)=0,"",VLOOKUP(B24,بيانات!A:L,12,FALSE)))
A25: {=IF(B25="","",ROW(7:7))} | C25: =IF(B25=0,"",VLOOKUP(B25,بيانات!A:H,4,FALSE)) | D25: =IF(B25=0,"",VLOOKUP(B25,بيانات!A:H,5,FALSE)) | E25: =IF(B25=0,"",VLOOKUP(B25,بيانات!A:M,13,FALSE)) | F25: =IF(B25=0,"",VLOOKUP(B25,بيانات!A:H,6,FALSE)) | J25: =IF(I25=0,"",VLOOKUP(I25,ورقة1!A:B,2,FALSE)) | K25: =IF(B25=0,"",IF(VLOOKUP(B25,بيانات!A:L,12,FALSE)=0,"",VLOOKUP(B25,بيانات!A:L,12,FALSE)))
A26: {=IF(B26="","",ROW(8:8))} | C26: =IF(B26=0,"",VLOOKUP(B26,بيانات!A:H,4,FALSE)) | D26: =IF(B26=0,"",VLOOKUP(B26,بيانات!A:H,5,FALSE)) | E26: =IF(B26=0,"",VLOOKUP(B26,بيانات!A:M,13,FALSE)) | F26: =IF(B26=0,"",VLOOKUP(B26,بيانات!A:H,6,FALSE)) | J26: =IF(I26=0,"",VLOOKUP(I26,ورقة1!A:B,2,FALSE)) | K26: =IF(B26=0,"",IF(VLOOKUP(B26,بيانات!A:L,12,FALSE)=0,"",VLOOKUP(B26,بيانات!A:L,12,FALSE)))
A27: {=IF(B27="","",ROW(9:9))} | C27: =IF(B27=0,"",VLOOKUP(B27,بيانات!A:H,4,FALSE)) | D27: =IF(B27=0,"",VLOOKUP(B27,بيانات!A:H,5,FALSE)) | E27: =IF(B27=0,"",VLOOKUP(B27,بيانات!A:M,13,FALSE)) | F27: =IF(B27=0,"",VLOOKUP(B27,بيانات!A:H,6,FALSE)) | J27: =IF(I27=0,"",VLOOKUP(I27,ورقة1!A:B,2,FALSE)) | K27: =IF(B27=0,"",IF(VLOOKUP(B27,بيانات!A:L,12,FALSE)=0,"",VLOOKUP(B27,بيانات!A:L,12,FALSE)))
A28: {=IF(B28="","",ROW(10:10))} | C28: =IF(B28=0,"",VLOOKUP(B28,بيانات!A:H,4,FALSE)) | D28: =IF(B28=0,"",VLOOKUP(B28,بيانات!A:H,5,FALSE)) | E28: =IF(B28=0,"",VLOOKUP(B28,بيانات!A:M,13,FALSE)) | F28: =IF(B28=0,"",VLOOKUP(B28,بيانات!A:H,6,FALSE)) | J28: =IF(I28=0,"",VLOOKUP(I28,ورقة1!A:B,2,FALSE)) | K28: =IF(B28=0,"",IF(VLOOKUP(B28,بيانات!A:L,12,FALSE)=0,"",VLOOKUP(B28,بيانات!A:L,12,FALSE)))
A29: {=IF(B29="","",ROW(11:11))} | C29: =IF(B29=0,"",VLOOKUP(B29,بيانات!A:H,4,FALSE)) | D29: =IF(B29=0,"",VLOOKUP(B29,بيانات!A:H,5,FALSE)) | E29: =IF(B29=0,"",VLOOKUP(B29,بيانات!A:M,13,FALSE)) | F29: =IF(B29=0,"",VLOOKUP(B29,بيانات!A:H,6,FALSE)) | J29: =IF(I29=0,"",VLOOKUP(I29,ورقة1!A:B,2,FALSE)) | K29: =IF(B29=0,"",IF(VLOOKUP(B29,بيانات!A:L,12,FALSE)=0,"",VLOOKUP(B29,بيانات!A:L,12,FALSE)))
A30: {=IF(B30="","",ROW(12:12))} | C30: =IF(B30=0,"",VLOOKUP(B30,بيانات!A:H,4,FALSE)) | D30: =IF(B30=0,"",VLOOKUP(B30,بيانات!A:H,5,FALSE)) | E30: =IF(B30=0,"",VLOOKUP(B30,بيانات!A:M,13,FALSE)) | F30: =IF(B30=0,"",VLOOKUP(B30,بيانات!A:H,6,FALSE)) | J30: =IF(I30=0,"",VLOOKUP(I30,ورقة1!A:B,2,FALSE)) | K30: =IF(B30=0,"",IF(VLOOKUP(B30,بيانات!A:L,12,FALSE)=0,"",VLOOKUP(B30,بيانات!A:L,12,FALSE)))
A31: {=IF(B31="","",ROW(13:13))} | C31: =IF(B31=0,"",VLOOKUP(B31,بيانات!A:H,4,FALSE)) | D31: =IF(B31=0,"",VLOOKUP(B31,بيانات!A:H,5,FALSE)) | E31: =IF(B31=0,"",VLOOKUP(B31,بيانات!A:M,13,FALSE)) | F31: =IF(B31=0,"",VLOOKUP(B31,بيانات!A:H,6,FALSE)) | J31: =IF(I31=0,"",VLOOKUP(I31,ورقة1!A:B,2,FALSE)) | K31: =IF(B31=0,"",IF(VLOOKUP(B31,بيانات!A:L,12,FALSE)=0,"",VLOOKUP(B31,بيانات!A:L,12,FALSE)))
A32: {=IF(B32="","",ROW(14:14))} | C32: =IF(B32=0,"",VLOOKUP(B32,بيانات!A:H,4,FALSE)) | D32: =IF(B32=0,"",VLOOKUP(B32,بيانات!A:H,5,FALSE)) | E32: =IF(B32=0,"",VLOOKUP(B32,بيانات!A:M,13,FALSE)) | F32: =IF(B32=0,"",VLOOKUP(B32,بيانات!A:H,6,FALSE)) | J32: =IF(I32=0,"",VLOOKUP(I32,ورقة1!A:B,2,FALSE)) | K32: =IF(B32=0,"",IF(VLOOKUP(B32,بيانات!A:L,12,FALSE)=0,"",VLOOKUP(B32,بيانات!A:L,12,FALSE)))
A33: {=IF(B33="","",ROW(15:15))} | C33: =IF(B33=0,"",VLOOKUP(B33,بيانات!A:H,4,FALSE)) | D33: =IF(B33=0,"",VLOOKUP(B33,بيانات!A:H,5,FALSE)) | E33: =IF(B33=0,"",VLOOKUP(B33,بيانات!A:M,13,FALSE)) | F33: =IF(B33=0,"",VLOOKUP(B33,بيانات!A:H,6,FALSE)) | J33: =IF(I33=0,"",VLOOKUP(I33,ورقة1!A:B,2,FALSE)) | K33: =IF(B33=0,"",IF(VLOOKUP(B33,بيانات!A:L,12,FALSE)=0,"",VLOOKUP(B33,بيانات!A:L,12,FALSE)))
A34: {=IF(B34="","",ROW(16:16))} | C34: =IF(B34=0,"",VLOOKUP(B34,بيانات!A:H,4,FALSE)) | D34: =IF(B34=0,"",VLOOKUP(B34,بيانات!A:H,5,FALSE)) | E34: =IF(B34=0,"",VLOOKUP(B34,بيانات!A:M,13,FALSE)) | F34: =IF(B34=0,"",VLOOKUP(B34,بيانات!A:H,6,FALSE)) | J34: =IF(I34=0,"",VLOOKUP(I34,ورقة1!A:B,2,FALSE)) | K34: =IF(B34=0,"",IF(VLOOKUP(B34,بيانات!A:L,12,FALSE)=0,"",VLOOKUP(B34,بيانات!A:L,12,FALSE)))
A35: {=IF(B35="","",ROW(17:17))} | C35: =IF(B35=0,"",VLOOKUP(B35,بيانات!A:H,4,FALSE)) | D35: =IF(B35=0,"",VLOOKUP(B35,بيانات!A:H,5,FALSE)) | E35: =IF(B35=0,"",VLOOKUP(B35,بيانات!A:M,13,FALSE)) | F35: =IF(B35=0,"",VLOOKUP(B35,بيانات!A:H,6,FALSE)) | J35: =IF(I35=0,"",VLOOKUP(I35,ورقة1!A:B,2,FALSE)) | K35: =IF(B35=0,"",IF(VLOOKUP(B35,بيانات!A:L,12,FALSE)=0,"",VLOOKUP(B35,بيانات!A:L,12,FALSE)))
A36: {=IF(B36="","",ROW(18:18))} | C36: =IF(B36=0,"",VLOOKUP(B36,بيانات!A:H,4,FALSE)) | D36: =IF(B36=0,"",VLOOKUP(B36,بيانات!A:H,5,FALSE)) | E36: =IF(B36=0,"",VLOOKUP(B36,بيانات!A:M,13,FALSE)) | F36: =IF(B36=0,"",VLOOKUP(B36,بيانات!A:H,6,FALSE)) | J36: =IF(I36=0,"",VLOOKUP(I36,ورقة1!A:B,2,FALSE)) | K36: =IF(B36=0,"",IF(VLOOKUP(B36,بيانات!A:L,12,FALSE)=0,"",VLOOKUP(B36,بيانات!A:L,12,FALSE)))
A37: {=IF(B37="","",ROW(19:19))} | C37: =IF(B37=0,"",VLOOKUP(B37,بيانات!A:H,4,FALSE)) | D37: =IF(B37=0,"",VLOOKUP(B37,بيانات!A:H,5,FALSE)) | E37: =IF(B37=0,"",VLOOKUP(B37,بيانات!A:M,13,FALSE)) | F37: =IF(B37=0,"",VLOOKUP(B37,بيانات!A:H,6,FALSE)) | J37: =IF(I37=0,"",VLOOKUP(I37,ورقة1!A:B,2,FALSE)) | K37: =IF(B37=0,"",IF(VLOOKUP(B37,بيانات!A:L,12,FALSE)=0,"",VLOOKUP(B37,بيانات!A:L,12,FALSE)))
A38: {=IF(B38="","",ROW(20:20))} | C38: =IF(B38=0,"",VLOOKUP(B38,بيانات!A:H,4,FALSE)) | D38: =IF(B38=0,"",VLOOKUP(B38,بيانات!A:H,5,FALSE)) | E38: =IF(B38=0,"",VLOOKUP(B38,بيانات!A:M,13,FALSE)) | F38: =IF(B38=0,"",VLOOKUP(B38,بيانات!A:H,6,FALSE)) | J38: =IF(I38=0,"",VLOOKUP(I38,ورقة1!A:B,2,FALSE)) | K38: =IF(B38=0,"",IF(VLOOKUP(B38,بيانات!A:L,12,FALSE)=0,"",VLOOKUP(B38,بيانات!A:L,12,FALSE)))
A39: {=IF(B39="","",ROW(21:21))} | C39: =IF(B39=0,"",VLOOKUP(B39,بيانات!A:H,4,FALSE)) | D39: =IF(B39=0,"",VLOOKUP(B39,بيانات!A:H,5,FALSE)) | E39: =IF(B39=0,"",VLOOKUP(B39,بيانات!A:M,13,FALSE)) | F39: =IF(B39=0,"",VLOOKUP(B39,بيانات!A:H,6,FALSE)) | J39: =IF(I39=0,"",VLOOKUP(I39,ورقة1!A:B,2,FALSE)) | K39: =IF(B39=0,"",IF(VLOOKUP(B39,بيانات!A:L,12,FALSE)=0,"",VLOOKUP(B39,بيانات!A:L,12,FALSE)))
A40: {=IF(B40="","",ROW(22:22))} | C40: =IF(B40=0,"",VLOOKUP(B40,بيانات!A:H,4,FALSE)) | D40: =IF(B40=0,"",VLOOKUP(B40,بيانات!A:H,5,FALSE)) | E40: =IF(B40=0,"",VLOOKUP(B40,بيانات!A:M,13,FALSE)) | F40: =IF(B40=0,"",VLOOKUP(B40,بيانات!A:H,6,FALSE)) | J40: =IF(I40=0,"",VLOOKUP(I40,ورقة1!A:B,2,FALSE)) | K40: =IF(B40=0,"",IF(VLOOKUP(B40,بيانات!A:L,12,FALSE)=0,"",VLOOKUP(B40,بيانات!A:L,12,FALSE)))
A41: {=IF(B41="","",ROW(23:23))} | C41: =IF(B41=0,"",VLOOKUP(B41,بيانات!A:H,4,FALSE)) | D41: =IF(B41=0,"",VLOOKUP(B41,بيانات!A:H,5,FALSE)) | E41: =IF(B41=0,"",VLOOKUP(B41,بيانات!A:M,13,FALSE)) | F41: =IF(B41=0,"",VLOOKUP(B41,بيانات!A:H,6,FALSE)) | J41: =IF(I41=0,"",VLOOKUP(I41,ورقة1!A:B,2,FALSE)) | K41: =IF(B41=0,"",IF(VLOOKUP(B41,بيانات!A:L,12,FALSE)=0,"",VLOOKUP(B41,بيانات!A:L,12,FALSE)))
A42: {=IF(B42="","",ROW(24:24))} | C42: =IF(B42=0,"",VLOOKUP(B42,بيانات!A:H,4,FALSE)) | D42: =IF(B42=0,"",VLOOKUP(B42,بيانات!A:H,5,FALSE)) | E42: =IF(B42=0,"",VLOOKUP(B42,بيانات!A:M,13,FALSE)) | F42: =IF(B42=0,"",VLOOKUP(B42,بيانات!A:H,6,FALSE)) | J42: =IF(I42=0,"",VLOOKUP(I42,ورقة1!A:B,2,FALSE)) | K42: =IF(B42=0,"",IF(VLOOKUP(B42,بيانات!A:L,12,FALSE)=0,"",VLOOKUP(B42,بيانات!A:L,12,FALSE)))
A44: رئيـس | B44: قسم الرقابة | C44: الموارد | D44: البشرية مدير فرع مكتب التربية | E44: مدير فـرع الخدمة المدنية | G44: رئيس المجلس المحلي
A46: طـارق | B46: الاديمــــــي | C46: رشيد | D46: القدسي عدنان علوان الشرجبي | E46: عـــــاصــــم الاديمي | G46: عبدالعزيز ردمان الشيباني
A49: {=IF(B49="","",ROW(25:25))} | C49: =IF(B49=0,"",VLOOKUP(B49,بيانات!A:H,4,FALSE)) | D49: =IF(B49=0,"",VLOOKUP(B49,بيانات!A:H,5,FALSE)) | E49: =IF(B49=0,"",VLOOKUP(B49,بيانات!A:M,13,FALSE)) | F49: =IF(B49=0,"",VLOOKUP(B49,بيانات!A:H,6,FALSE)) | J49: =IF(I49=0,"",VLOOKUP(I49,ورقة1!A:B,2,FALSE)) | K49: =IF(B49=0,"",IF(VLOOKUP(B49,بيانات!A:L,12,FALSE)=0,"",VLOOKUP(B49,بيانات!A:L,12,FALSE))) | L49: نموذج الغياب الموحد - 2 ( أغسطس 2024 )
A50: {=IF(B50="","",ROW(26:26))} | C50: =IF(B50=0,"",VLOOKUP(B50,بيانات!A:H,4,FALSE)) | D50: =IF(B50=0,"",VLOOKUP(B50,بيانات!A:H,5,FALSE)) | E50: =IF(B50=0,"",VLOOKUP(B50,بيانات!A:M,13,FALSE)) | F50: =IF(B50=0,"",VLOOKUP(B50,بيانات!A:H,6,FALSE)) | J50: =IF(I50=0,"",VLOOKUP(I50,ورقة1!A:B,2,FALSE)) | K50: =IF(B50=0,"",IF(VLOOKUP(B50,بيانات!A:L,12,FALSE)=0,"",VLOOKUP(B50,بيانات!A:L,12,FALSE)))
A51: {=IF(B51="","",ROW(27:27))} | C51: =IF(B51=0,"",VLOOKUP(B51,بيانات!A:H,4,FALSE)) | D51: =IF(B51=0,"",VLOOKUP(B51,بيانات!A:H,5,FALSE)) | E51: =IF(B51=0,"",VLOOKUP(B51,بيانات!A:M,13,FALSE)) | F51: =IF(B51=0,"",VLOOKUP(B51,بيانات!A:H,6,FALSE)) | J51: =IF(I51=0,"",VLOOKUP(I51,ورقة1!A:B,2,FALSE)) | K51: =IF(B51=0,"",IF(VLOOKUP(B51,بيانات!A:L,12,FALSE)=0,"",VLOOKUP(B51,بيانات!A:L,12,FALSE)))
...

Sheet ورقة2
